Not Found: /b/
Not Found: /b/
Not Found: /b/
Traceback (most recent call last):
  File "/home/dgfsmg/repositories/dgfs_back/passenger_wsgi.py", line 1, in <module>
    from MainRoot.wsgi import application
  File "/home/dgfsmg/repositories/dgfs_back/MainRoot/wsgi.py", line 16, in <module>
    application = get_wsgi_application()
  File "/home/dgfsmg/virtualenv/repositories/dgfs_back/3.10/lib/python3.10/site-packages/django/core/wsgi.py", line 12, in get_wsgi_application
    django.setup(set_prefix=False)
  File "/home/dgfsmg/virtualenv/repositories/dgfs_back/3.10/lib/python3.10/site-packages/django/__init__.py", line 19, in setup
    configure_logging(settings.LOGGING_CONFIG, settings.LOGGING)
  File "/home/dgfsmg/virtualenv/repositories/dgfs_back/3.10/lib/python3.10/site-packages/django/conf/__init__.py", line 102, in __getattr__
    self._setup(name)
  File "/home/dgfsmg/virtualenv/repositories/dgfs_back/3.10/lib/python3.10/site-packages/django/conf/__init__.py", line 89, in _setup
    self._wrapped = Settings(settings_module)
  File "/home/dgfsmg/virtualenv/repositories/dgfs_back/3.10/lib/python3.10/site-packages/django/conf/__init__.py", line 217, in __init__
    mod = importlib.import_module(self.SETTINGS_MODULE)
  File "/opt/alt/python310/lib64/python3.10/importlib/__init__.py", line 126, in import_module
    return _bootstrap._gcd_import(name[level:], package, level)
  File "/home/dgfsmg/repositories/dgfs_back/MainRoot/settings.py", line 147
    STATIC_URL = '/static/'STATICFILES_STORAGE = 'django.contrib.staticfiles.storage.ManifestStaticFilesStorage'
                           ^^^^^^^^^^^^^^^^^^^
SyntaxError: invalid syntax
Traceback (most recent call last):
  File "/home/dgfsmg/repositories/dgfs_back/passenger_wsgi.py", line 1, in <module>
    from MainRoot.wsgi import application
  File "/home/dgfsmg/repositories/dgfs_back/MainRoot/wsgi.py", line 16, in <module>
    application = get_wsgi_application()
  File "/home/dgfsmg/virtualenv/repositories/dgfs_back/3.10/lib/python3.10/site-packages/django/core/wsgi.py", line 12, in get_wsgi_application
    django.setup(set_prefix=False)
  File "/home/dgfsmg/virtualenv/repositories/dgfs_back/3.10/lib/python3.10/site-packages/django/__init__.py", line 19, in setup
    configure_logging(settings.LOGGING_CONFIG, settings.LOGGING)
  File "/home/dgfsmg/virtualenv/repositories/dgfs_back/3.10/lib/python3.10/site-packages/django/conf/__init__.py", line 102, in __getattr__
    self._setup(name)
  File "/home/dgfsmg/virtualenv/repositories/dgfs_back/3.10/lib/python3.10/site-packages/django/conf/__init__.py", line 89, in _setup
    self._wrapped = Settings(settings_module)
  File "/home/dgfsmg/virtualenv/repositories/dgfs_back/3.10/lib/python3.10/site-packages/django/conf/__init__.py", line 217, in __init__
    mod = importlib.import_module(self.SETTINGS_MODULE)
  File "/opt/alt/python310/lib64/python3.10/importlib/__init__.py", line 126, in import_module
    return _bootstrap._gcd_import(name[level:], package, level)
  File "/home/dgfsmg/repositories/dgfs_back/MainRoot/settings.py", line 147
    STATIC_URL = '/static/'STATICFILES_STORAGE = 'django.contrib.staticfiles.storage.ManifestStaticFilesStorage'
                           ^^^^^^^^^^^^^^^^^^^
SyntaxError: invalid syntax
[UID:3250][1663962] Child process with pid: 1664287 was killed by signal: 15, core dumped: no
Not Found: /b/
Not Found: /b/
Not Found: /b/
Not Found: /b/
Not Found: /b/
Not Found: /b/
Not Found: /b/
[ERROR] [UID:3250][2539447] wsgiAppHandler pApp->start_response() return NULL.
Traceback (most recent call last):
  File "/home/dgfsmg/virtualenv/repositories/dgfs_back/3.10/lib/python3.10/site-packages/django/core/handlers/exception.py", line 55, in inner
    response = get_response(request)
  File "/home/dgfsmg/virtualenv/repositories/dgfs_back/3.10/lib/python3.10/site-packages/django/core/handlers/base.py", line 181, in _get_response
    callback, callback_args, callback_kwargs = self.resolve_request(request)
  File "/home/dgfsmg/virtualenv/repositories/dgfs_back/3.10/lib/python3.10/site-packages/django/core/handlers/base.py", line 313, in resolve_request
    resolver_match = resolver.resolve(request.path_info)
  File "/home/dgfsmg/virtualenv/repositories/dgfs_back/3.10/lib/python3.10/site-packages/django/urls/resolvers.py", line 663, in resolve
    for pattern in self.url_patterns:
  File "/home/dgfsmg/virtualenv/repositories/dgfs_back/3.10/lib/python3.10/site-packages/django/utils/functional.py", line 57, in __get__
    res = instance.__dict__[self.name] = self.func(instance)
  File "/home/dgfsmg/virtualenv/repositories/dgfs_back/3.10/lib/python3.10/site-packages/django/urls/resolvers.py", line 715, in url_patterns
    patterns = getattr(self.urlconf_module, "urlpatterns", self.urlconf_module)
  File "/home/dgfsmg/virtualenv/repositories/dgfs_back/3.10/lib/python3.10/site-packages/django/utils/functional.py", line 57, in __get__
    res = instance.__dict__[self.name] = self.func(instance)
  File "/home/dgfsmg/virtualenv/repositories/dgfs_back/3.10/lib/python3.10/site-packages/django/urls/resolvers.py", line 708, in urlconf_module
    return import_module(self.urlconf_name)
  File "/opt/alt/python310/lib64/python3.10/importlib/__init__.py", line 126, in import_module
    return _bootstrap._gcd_import(name[level:], package, level)
  File "<frozen importlib._bootstrap>", line 1050, in _gcd_import
  File "<frozen importlib._bootstrap>", line 1027, in _find_and_load
  File "<frozen importlib._bootstrap>", line 1006, in _find_and_load_unlocked
  File "<frozen importlib._bootstrap>", line 688, in _load_unlocked
  File "<frozen importlib._bootstrap_external>", line 879, in exec_module
  File "<frozen importlib._bootstrap_external>", line 1017, in get_code
  File "<frozen importlib._bootstrap_external>", line 947, in source_to_code
  File "<frozen importlib._bootstrap>", line 241, in _call_with_frames_removed
  File "/home/dgfsmg/repositories/dgfs_back/MainRoot/urls.py", line 29
    urlpatterns += static(settings.MEDIA_URL, document_root=settings.MEDIA_ROOT , staticfiles_urlpatterns())
                                                                                                           ^
SyntaxError: positional argument follows keyword argument

During handling of the above exception, another exception occurred:

Traceback (most recent call last):
  File "/home/dgfsmg/virtualenv/repositories/dgfs_back/3.10/lib/python3.10/site-packages/django/core/handlers/exception.py", line 55, in inner
    response = get_response(request)
  File "/home/dgfsmg/virtualenv/repositories/dgfs_back/3.10/lib/python3.10/site-packages/django/utils/deprecation.py", line 134, in __call__
    response = response or self.get_response(request)
  File "/home/dgfsmg/virtualenv/repositories/dgfs_back/3.10/lib/python3.10/site-packages/django/core/handlers/exception.py", line 57, in inner
    response = response_for_exception(request, exc)
  File "/home/dgfsmg/virtualenv/repositories/dgfs_back/3.10/lib/python3.10/site-packages/django/core/handlers/exception.py", line 140, in response_for_exception
    response = handle_uncaught_exception(
  File "/home/dgfsmg/virtualenv/repositories/dgfs_back/3.10/lib/python3.10/site-packages/django/core/handlers/exception.py", line 181, in handle_uncaught_exception
    return debug.technical_500_response(request, *exc_info)
  File "/home/dgfsmg/virtualenv/repositories/dgfs_back/3.10/lib/python3.10/site-packages/django/views/debug.py", line 67, in technical_500_response
    html = reporter.get_traceback_html()
  File "/home/dgfsmg/virtualenv/repositories/dgfs_back/3.10/lib/python3.10/site-packages/django/views/debug.py", line 410, in get_traceback_html
    c = Context(self.get_traceback_data(), use_l10n=False)
  File "/home/dgfsmg/virtualenv/repositories/dgfs_back/3.10/lib/python3.10/site-packages/django/views/debug.py", line 393, in get_traceback_data
    c["raising_view_name"] = get_caller(self.request)
  File "/home/dgfsmg/virtualenv/repositories/dgfs_back/3.10/lib/python3.10/site-packages/django/views/debug.py", line 100, in get_caller
    resolver_match = resolve(request.path)
  File "/home/dgfsmg/virtualenv/repositories/dgfs_back/3.10/lib/python3.10/site-packages/django/urls/base.py", line 24, in resolve
    return get_resolver(urlconf).resolve(path)
  File "/home/dgfsmg/virtualenv/repositories/dgfs_back/3.10/lib/python3.10/site-packages/django/urls/resolvers.py", line 663, in resolve
    for pattern in self.url_patterns:
  File "/home/dgfsmg/virtualenv/repositories/dgfs_back/3.10/lib/python3.10/site-packages/django/utils/functional.py", line 57, in __get__
    res = instance.__dict__[self.name] = self.func(instance)
  File "/home/dgfsmg/virtualenv/repositories/dgfs_back/3.10/lib/python3.10/site-packages/django/urls/resolvers.py", line 715, in url_patterns
    patterns = getattr(self.urlconf_module, "urlpatterns", self.urlconf_module)
  File "/home/dgfsmg/virtualenv/repositories/dgfs_back/3.10/lib/python3.10/site-packages/django/utils/functional.py", line 57, in __get__
    res = instance.__dict__[self.name] = self.func(instance)
  File "/home/dgfsmg/virtualenv/repositories/dgfs_back/3.10/lib/python3.10/site-packages/django/urls/resolvers.py", line 708, in urlconf_module
    return import_module(self.urlconf_name)
  File "/opt/alt/python310/lib64/python3.10/importlib/__init__.py", line 126, in import_module
    return _bootstrap._gcd_import(name[level:], package, level)
  File "<frozen importlib._bootstrap>", line 1050, in _gcd_import
  File "<frozen importlib._bootstrap>", line 1027, in _find_and_load
  File "<frozen importlib._bootstrap>", line 1006, in _find_and_load_unlocked
  File "<frozen importlib._bootstrap>", line 688, in _load_unlocked
  File "<frozen importlib._bootstrap_external>", line 879, in exec_module
  File "<frozen importlib._bootstrap_external>", line 1017, in get_code
  File "<frozen importlib._bootstrap_external>", line 947, in source_to_code
  File "<frozen importlib._bootstrap>", line 241, in _call_with_frames_removed
  File "/home/dgfsmg/repositories/dgfs_back/MainRoot/urls.py", line 29
    urlpatterns += static(settings.MEDIA_URL, document_root=settings.MEDIA_ROOT , staticfiles_urlpatterns())
                                                                                                           ^
SyntaxError: positional argument follows keyword argument

During handling of the above exception, another exception occurred:

Traceback (most recent call last):
  File "/home/dgfsmg/virtualenv/repositories/dgfs_back/3.10/lib/python3.10/site-packages/django/core/handlers/exception.py", line 55, in inner
    response = get_response(request)
  File "/home/dgfsmg/virtualenv/repositories/dgfs_back/3.10/lib/python3.10/site-packages/django/utils/deprecation.py", line 134, in __call__
    response = response or self.get_response(request)
  File "/home/dgfsmg/virtualenv/repositories/dgfs_back/3.10/lib/python3.10/site-packages/django/core/handlers/exception.py", line 57, in inner
    response = response_for_exception(request, exc)
  File "/home/dgfsmg/virtualenv/repositories/dgfs_back/3.10/lib/python3.10/site-packages/django/core/handlers/exception.py", line 140, in response_for_exception
    response = handle_uncaught_exception(
  File "/home/dgfsmg/virtualenv/repositories/dgfs_back/3.10/lib/python3.10/site-packages/django/core/handlers/exception.py", line 181, in handle_uncaught_exception
    return debug.technical_500_response(request, *exc_info)
  File "/home/dgfsmg/virtualenv/repositories/dgfs_back/3.10/lib/python3.10/site-packages/django/views/debug.py", line 67, in technical_500_response
    html = reporter.get_traceback_html()
  File "/home/dgfsmg/virtualenv/repositories/dgfs_back/3.10/lib/python3.10/site-packages/django/views/debug.py", line 410, in get_traceback_html
    c = Context(self.get_traceback_data(), use_l10n=False)
  File "/home/dgfsmg/virtualenv/repositories/dgfs_back/3.10/lib/python3.10/site-packages/django/views/debug.py", line 393, in get_traceback_data
    c["raising_view_name"] = get_caller(self.request)
  File "/home/dgfsmg/virtualenv/repositories/dgfs_back/3.10/lib/python3.10/site-packages/django/views/debug.py", line 100, in get_caller
    resolver_match = resolve(request.path)
  File "/home/dgfsmg/virtualenv/repositories/dgfs_back/3.10/lib/python3.10/site-packages/django/urls/base.py", line 24, in resolve
    return get_resolver(urlconf).resolve(path)
  File "/home/dgfsmg/virtualenv/repositories/dgfs_back/3.10/lib/python3.10/site-packages/django/urls/resolvers.py", line 663, in resolve
    for pattern in self.url_patterns:
  File "/home/dgfsmg/virtualenv/repositories/dgfs_back/3.10/lib/python3.10/site-packages/django/utils/functional.py", line 57, in __get__
    res = instance.__dict__[self.name] = self.func(instance)
  File "/home/dgfsmg/virtualenv/repositories/dgfs_back/3.10/lib/python3.10/site-packages/django/urls/resolvers.py", line 715, in url_patterns
    patterns = getattr(self.urlconf_module, "urlpatterns", self.urlconf_module)
  File "/home/dgfsmg/virtualenv/repositories/dgfs_back/3.10/lib/python3.10/site-packages/django/utils/functional.py", line 57, in __get__
    res = instance.__dict__[self.name] = self.func(instance)
  File "/home/dgfsmg/virtualenv/repositories/dgfs_back/3.10/lib/python3.10/site-packages/django/urls/resolvers.py", line 708, in urlconf_module
    return import_module(self.urlconf_name)
  File "/opt/alt/python310/lib64/python3.10/importlib/__init__.py", line 126, in import_module
    return _bootstrap._gcd_import(name[level:], package, level)
  File "<frozen importlib._bootstrap>", line 1050, in _gcd_import
  File "<frozen importlib._bootstrap>", line 1027, in _find_and_load
  File "<frozen importlib._bootstrap>", line 1006, in _find_and_load_unlocked
  File "<frozen importlib._bootstrap>", line 688, in _load_unlocked
  File "<frozen importlib._bootstrap_external>", line 879, in exec_module
  File "<frozen importlib._bootstrap_external>", line 1017, in get_code
  File "<frozen importlib._bootstrap_external>", line 947, in source_to_code
  File "<frozen importlib._bootstrap>", line 241, in _call_with_frames_removed
  File "/home/dgfsmg/repositories/dgfs_back/MainRoot/urls.py", line 29
    urlpatterns += static(settings.MEDIA_URL, document_root=settings.MEDIA_ROOT , staticfiles_urlpatterns())
                                                                                                           ^
SyntaxError: positional argument follows keyword argument

During handling of the above exception, another exception occurred:

Traceback (most recent call last):
  File "/home/dgfsmg/virtualenv/repositories/dgfs_back/3.10/lib/python3.10/site-packages/django/core/handlers/exception.py", line 55, in inner
    response = get_response(request)
  File "/home/dgfsmg/virtualenv/repositories/dgfs_back/3.10/lib/python3.10/site-packages/django/utils/deprecation.py", line 134, in __call__
    response = response or self.get_response(request)
  File "/home/dgfsmg/virtualenv/repositories/dgfs_back/3.10/lib/python3.10/site-packages/django/core/handlers/exception.py", line 57, in inner
    response = response_for_exception(request, exc)
  File "/home/dgfsmg/virtualenv/repositories/dgfs_back/3.10/lib/python3.10/site-packages/django/core/handlers/exception.py", line 140, in response_for_exception
    response = handle_uncaught_exception(
  File "/home/dgfsmg/virtualenv/repositories/dgfs_back/3.10/lib/python3.10/site-packages/django/core/handlers/exception.py", line 181, in handle_uncaught_exception
    return debug.technical_500_response(request, *exc_info)
  File "/home/dgfsmg/virtualenv/repositories/dgfs_back/3.10/lib/python3.10/site-packages/django/views/debug.py", line 67, in technical_500_response
    html = reporter.get_traceback_html()
  File "/home/dgfsmg/virtualenv/repositories/dgfs_back/3.10/lib/python3.10/site-packages/django/views/debug.py", line 410, in get_traceback_html
    c = Context(self.get_traceback_data(), use_l10n=False)
  File "/home/dgfsmg/virtualenv/repositories/dgfs_back/3.10/lib/python3.10/site-packages/django/views/debug.py", line 393, in get_traceback_data
    c["raising_view_name"] = get_caller(self.request)
  File "/home/dgfsmg/virtualenv/repositories/dgfs_back/3.10/lib/python3.10/site-packages/django/views/debug.py", line 100, in get_caller
    resolver_match = resolve(request.path)
  File "/home/dgfsmg/virtualenv/repositories/dgfs_back/3.10/lib/python3.10/site-packages/django/urls/base.py", line 24, in resolve
    return get_resolver(urlconf).resolve(path)
  File "/home/dgfsmg/virtualenv/repositories/dgfs_back/3.10/lib/python3.10/site-packages/django/urls/resolvers.py", line 663, in resolve
    for pattern in self.url_patterns:
  File "/home/dgfsmg/virtualenv/repositories/dgfs_back/3.10/lib/python3.10/site-packages/django/utils/functional.py", line 57, in __get__
    res = instance.__dict__[self.name] = self.func(instance)
  File "/home/dgfsmg/virtualenv/repositories/dgfs_back/3.10/lib/python3.10/site-packages/django/urls/resolvers.py", line 715, in url_patterns
    patterns = getattr(self.urlconf_module, "urlpatterns", self.urlconf_module)
  File "/home/dgfsmg/virtualenv/repositories/dgfs_back/3.10/lib/python3.10/site-packages/django/utils/functional.py", line 57, in __get__
    res = instance.__dict__[self.name] = self.func(instance)
  File "/home/dgfsmg/virtualenv/repositories/dgfs_back/3.10/lib/python3.10/site-packages/django/urls/resolvers.py", line 708, in urlconf_module
    return import_module(self.urlconf_name)
  File "/opt/alt/python310/lib64/python3.10/importlib/__init__.py", line 126, in import_module
    return _bootstrap._gcd_import(name[level:], package, level)
  File "<frozen importlib._bootstrap>", line 1050, in _gcd_import
  File "<frozen importlib._bootstrap>", line 1027, in _find_and_load
  File "<frozen importlib._bootstrap>", line 1006, in _find_and_load_unlocked
  File "<frozen importlib._bootstrap>", line 688, in _load_unlocked
  File "<frozen importlib._bootstrap_external>", line 879, in exec_module
  File "<frozen importlib._bootstrap_external>", line 1017, in get_code
  File "<frozen importlib._bootstrap_external>", line 947, in source_to_code
  File "<frozen importlib._bootstrap>", line 241, in _call_with_frames_removed
  File "/home/dgfsmg/repositories/dgfs_back/MainRoot/urls.py", line 29
    urlpatterns += static(settings.MEDIA_URL, document_root=settings.MEDIA_ROOT , staticfiles_urlpatterns())
                                                                                                           ^
SyntaxError: positional argument follows keyword argument

During handling of the above exception, another exception occurred:

Traceback (most recent call last):
  File "/home/dgfsmg/virtualenv/repositories/dgfs_back/3.10/lib/python3.10/site-packages/django/core/handlers/exception.py", line 55, in inner
    response = get_response(request)
  File "/home/dgfsmg/virtualenv/repositories/dgfs_back/3.10/lib/python3.10/site-packages/django/utils/deprecation.py", line 134, in __call__
    response = response or self.get_response(request)
  File "/home/dgfsmg/virtualenv/repositories/dgfs_back/3.10/lib/python3.10/site-packages/django/core/handlers/exception.py", line 57, in inner
    response = response_for_exception(request, exc)
  File "/home/dgfsmg/virtualenv/repositories/dgfs_back/3.10/lib/python3.10/site-packages/django/core/handlers/exception.py", line 140, in response_for_exception
    response = handle_uncaught_exception(
  File "/home/dgfsmg/virtualenv/repositories/dgfs_back/3.10/lib/python3.10/site-packages/django/core/handlers/exception.py", line 181, in handle_uncaught_exception
    return debug.technical_500_response(request, *exc_info)
  File "/home/dgfsmg/virtualenv/repositories/dgfs_back/3.10/lib/python3.10/site-packages/django/views/debug.py", line 67, in technical_500_response
    html = reporter.get_traceback_html()
  File "/home/dgfsmg/virtualenv/repositories/dgfs_back/3.10/lib/python3.10/site-packages/django/views/debug.py", line 410, in get_traceback_html
    c = Context(self.get_traceback_data(), use_l10n=False)
  File "/home/dgfsmg/virtualenv/repositories/dgfs_back/3.10/lib/python3.10/site-packages/django/views/debug.py", line 393, in get_traceback_data
    c["raising_view_name"] = get_caller(self.request)
  File "/home/dgfsmg/virtualenv/repositories/dgfs_back/3.10/lib/python3.10/site-packages/django/views/debug.py", line 100, in get_caller
    resolver_match = resolve(request.path)
  File "/home/dgfsmg/virtualenv/repositories/dgfs_back/3.10/lib/python3.10/site-packages/django/urls/base.py", line 24, in resolve
    return get_resolver(urlconf).resolve(path)
  File "/home/dgfsmg/virtualenv/repositories/dgfs_back/3.10/lib/python3.10/site-packages/django/urls/resolvers.py", line 663, in resolve
    for pattern in self.url_patterns:
  File "/home/dgfsmg/virtualenv/repositories/dgfs_back/3.10/lib/python3.10/site-packages/django/utils/functional.py", line 57, in __get__
    res = instance.__dict__[self.name] = self.func(instance)
  File "/home/dgfsmg/virtualenv/repositories/dgfs_back/3.10/lib/python3.10/site-packages/django/urls/resolvers.py", line 715, in url_patterns
    patterns = getattr(self.urlconf_module, "urlpatterns", self.urlconf_module)
  File "/home/dgfsmg/virtualenv/repositories/dgfs_back/3.10/lib/python3.10/site-packages/django/utils/functional.py", line 57, in __get__
    res = instance.__dict__[self.name] = self.func(instance)
  File "/home/dgfsmg/virtualenv/repositories/dgfs_back/3.10/lib/python3.10/site-packages/django/urls/resolvers.py", line 708, in urlconf_module
    return import_module(self.urlconf_name)
  File "/opt/alt/python310/lib64/python3.10/importlib/__init__.py", line 126, in import_module
    return _bootstrap._gcd_import(name[level:], package, level)
  File "<frozen importlib._bootstrap>", line 1050, in _gcd_import
  File "<frozen importlib._bootstrap>", line 1027, in _find_and_load
  File "<frozen importlib._bootstrap>", line 1006, in _find_and_load_unlocked
  File "<frozen importlib._bootstrap>", line 688, in _load_unlocked
  File "<frozen importlib._bootstrap_external>", line 879, in exec_module
  File "<frozen importlib._bootstrap_external>", line 1017, in get_code
  File "<frozen importlib._bootstrap_external>", line 947, in source_to_code
  File "<frozen importlib._bootstrap>", line 241, in _call_with_frames_removed
  File "/home/dgfsmg/repositories/dgfs_back/MainRoot/urls.py", line 29
    urlpatterns += static(settings.MEDIA_URL, document_root=settings.MEDIA_ROOT , staticfiles_urlpatterns())
                                                                                                           ^
SyntaxError: positional argument follows keyword argument

During handling of the above exception, another exception occurred:

Traceback (most recent call last):
  File "/home/dgfsmg/virtualenv/repositories/dgfs_back/3.10/lib/python3.10/site-packages/django/core/handlers/exception.py", line 55, in inner
    response = get_response(request)
  File "/home/dgfsmg/virtualenv/repositories/dgfs_back/3.10/lib/python3.10/site-packages/django/utils/deprecation.py", line 134, in __call__
    response = response or self.get_response(request)
  File "/home/dgfsmg/virtualenv/repositories/dgfs_back/3.10/lib/python3.10/site-packages/django/core/handlers/exception.py", line 57, in inner
    response = response_for_exception(request, exc)
  File "/home/dgfsmg/virtualenv/repositories/dgfs_back/3.10/lib/python3.10/site-packages/django/core/handlers/exception.py", line 140, in response_for_exception
    response = handle_uncaught_exception(
  File "/home/dgfsmg/virtualenv/repositories/dgfs_back/3.10/lib/python3.10/site-packages/django/core/handlers/exception.py", line 181, in handle_uncaught_exception
    return debug.technical_500_response(request, *exc_info)
  File "/home/dgfsmg/virtualenv/repositories/dgfs_back/3.10/lib/python3.10/site-packages/django/views/debug.py", line 67, in technical_500_response
    html = reporter.get_traceback_html()
  File "/home/dgfsmg/virtualenv/repositories/dgfs_back/3.10/lib/python3.10/site-packages/django/views/debug.py", line 410, in get_traceback_html
    c = Context(self.get_traceback_data(), use_l10n=False)
  File "/home/dgfsmg/virtualenv/repositories/dgfs_back/3.10/lib/python3.10/site-packages/django/views/debug.py", line 393, in get_traceback_data
    c["raising_view_name"] = get_caller(self.request)
  File "/home/dgfsmg/virtualenv/repositories/dgfs_back/3.10/lib/python3.10/site-packages/django/views/debug.py", line 100, in get_caller
    resolver_match = resolve(request.path)
  File "/home/dgfsmg/virtualenv/repositories/dgfs_back/3.10/lib/python3.10/site-packages/django/urls/base.py", line 24, in resolve
    return get_resolver(urlconf).resolve(path)
  File "/home/dgfsmg/virtualenv/repositories/dgfs_back/3.10/lib/python3.10/site-packages/django/urls/resolvers.py", line 663, in resolve
    for pattern in self.url_patterns:
  File "/home/dgfsmg/virtualenv/repositories/dgfs_back/3.10/lib/python3.10/site-packages/django/utils/functional.py", line 57, in __get__
    res = instance.__dict__[self.name] = self.func(instance)
  File "/home/dgfsmg/virtualenv/repositories/dgfs_back/3.10/lib/python3.10/site-packages/django/urls/resolvers.py", line 715, in url_patterns
    patterns = getattr(self.urlconf_module, "urlpatterns", self.urlconf_module)
  File "/home/dgfsmg/virtualenv/repositories/dgfs_back/3.10/lib/python3.10/site-packages/django/utils/functional.py", line 57, in __get__
    res = instance.__dict__[self.name] = self.func(instance)
  File "/home/dgfsmg/virtualenv/repositories/dgfs_back/3.10/lib/python3.10/site-packages/django/urls/resolvers.py", line 708, in urlconf_module
    return import_module(self.urlconf_name)
  File "/opt/alt/python310/lib64/python3.10/importlib/__init__.py", line 126, in import_module
    return _bootstrap._gcd_import(name[level:], package, level)
  File "<frozen importlib._bootstrap>", line 1050, in _gcd_import
  File "<frozen importlib._bootstrap>", line 1027, in _find_and_load
  File "<frozen importlib._bootstrap>", line 1006, in _find_and_load_unlocked
  File "<frozen importlib._bootstrap>", line 688, in _load_unlocked
  File "<frozen importlib._bootstrap_external>", line 879, in exec_module
  File "<frozen importlib._bootstrap_external>", line 1017, in get_code
  File "<frozen importlib._bootstrap_external>", line 947, in source_to_code
  File "<frozen importlib._bootstrap>", line 241, in _call_with_frames_removed
  File "/home/dgfsmg/repositories/dgfs_back/MainRoot/urls.py", line 29
    urlpatterns += static(settings.MEDIA_URL, document_root=settings.MEDIA_ROOT , staticfiles_urlpatterns())
                                                                                                           ^
SyntaxError: positional argument follows keyword argument

During handling of the above exception, another exception occurred:

Traceback (most recent call last):
  File "/home/dgfsmg/virtualenv/repositories/dgfs_back/3.10/lib/python3.10/site-packages/django/core/handlers/exception.py", line 55, in inner
    response = get_response(request)
  File "/home/dgfsmg/virtualenv/repositories/dgfs_back/3.10/lib/python3.10/site-packages/django/utils/deprecation.py", line 134, in __call__
    response = response or self.get_response(request)
  File "/home/dgfsmg/virtualenv/repositories/dgfs_back/3.10/lib/python3.10/site-packages/django/core/handlers/exception.py", line 57, in inner
    response = response_for_exception(request, exc)
  File "/home/dgfsmg/virtualenv/repositories/dgfs_back/3.10/lib/python3.10/site-packages/django/core/handlers/exception.py", line 140, in response_for_exception
    response = handle_uncaught_exception(
  File "/home/dgfsmg/virtualenv/repositories/dgfs_back/3.10/lib/python3.10/site-packages/django/core/handlers/exception.py", line 181, in handle_uncaught_exception
    return debug.technical_500_response(request, *exc_info)
  File "/home/dgfsmg/virtualenv/repositories/dgfs_back/3.10/lib/python3.10/site-packages/django/views/debug.py", line 67, in technical_500_response
    html = reporter.get_traceback_html()
  File "/home/dgfsmg/virtualenv/repositories/dgfs_back/3.10/lib/python3.10/site-packages/django/views/debug.py", line 410, in get_traceback_html
    c = Context(self.get_traceback_data(), use_l10n=False)
  File "/home/dgfsmg/virtualenv/repositories/dgfs_back/3.10/lib/python3.10/site-packages/django/views/debug.py", line 393, in get_traceback_data
    c["raising_view_name"] = get_caller(self.request)
  File "/home/dgfsmg/virtualenv/repositories/dgfs_back/3.10/lib/python3.10/site-packages/django/views/debug.py", line 100, in get_caller
    resolver_match = resolve(request.path)
  File "/home/dgfsmg/virtualenv/repositories/dgfs_back/3.10/lib/python3.10/site-packages/django/urls/base.py", line 24, in resolve
    return get_resolver(urlconf).resolve(path)
  File "/home/dgfsmg/virtualenv/repositories/dgfs_back/3.10/lib/python3.10/site-packages/django/urls/resolvers.py", line 663, in resolve
    for pattern in self.url_patterns:
  File "/home/dgfsmg/virtualenv/repositories/dgfs_back/3.10/lib/python3.10/site-packages/django/utils/functional.py", line 57, in __get__
    res = instance.__dict__[self.name] = self.func(instance)
  File "/home/dgfsmg/virtualenv/repositories/dgfs_back/3.10/lib/python3.10/site-packages/django/urls/resolvers.py", line 715, in url_patterns
    patterns = getattr(self.urlconf_module, "urlpatterns", self.urlconf_module)
  File "/home/dgfsmg/virtualenv/repositories/dgfs_back/3.10/lib/python3.10/site-packages/django/utils/functional.py", line 57, in __get__
    res = instance.__dict__[self.name] = self.func(instance)
  File "/home/dgfsmg/virtualenv/repositories/dgfs_back/3.10/lib/python3.10/site-packages/django/urls/resolvers.py", line 708, in urlconf_module
    return import_module(self.urlconf_name)
  File "/opt/alt/python310/lib64/python3.10/importlib/__init__.py", line 126, in import_module
    return _bootstrap._gcd_import(name[level:], package, level)
  File "<frozen importlib._bootstrap>", line 1050, in _gcd_import
  File "<frozen importlib._bootstrap>", line 1027, in _find_and_load
  File "<frozen importlib._bootstrap>", line 1006, in _find_and_load_unlocked
  File "<frozen importlib._bootstrap>", line 688, in _load_unlocked
  File "<frozen importlib._bootstrap_external>", line 879, in exec_module
  File "<frozen importlib._bootstrap_external>", line 1017, in get_code
  File "<frozen importlib._bootstrap_external>", line 947, in source_to_code
  File "<frozen importlib._bootstrap>", line 241, in _call_with_frames_removed
  File "/home/dgfsmg/repositories/dgfs_back/MainRoot/urls.py", line 29
    urlpatterns += static(settings.MEDIA_URL, document_root=settings.MEDIA_ROOT , staticfiles_urlpatterns())
                                                                                                           ^
SyntaxError: positional argument follows keyword argument

During handling of the above exception, another exception occurred:

Traceback (most recent call last):
  File "/home/dgfsmg/virtualenv/repositories/dgfs_back/3.10/lib/python3.10/site-packages/django/core/handlers/exception.py", line 55, in inner
    response = get_response(request)
  File "/home/dgfsmg/virtualenv/repositories/dgfs_back/3.10/lib/python3.10/site-packages/whitenoise/middleware.py", line 124, in __call__
    return self.get_response(request)
  File "/home/dgfsmg/virtualenv/repositories/dgfs_back/3.10/lib/python3.10/site-packages/django/core/handlers/exception.py", line 57, in inner
    response = response_for_exception(request, exc)
  File "/home/dgfsmg/virtualenv/repositories/dgfs_back/3.10/lib/python3.10/site-packages/django/core/handlers/exception.py", line 140, in response_for_exception
    response = handle_uncaught_exception(
  File "/home/dgfsmg/virtualenv/repositories/dgfs_back/3.10/lib/python3.10/site-packages/django/core/handlers/exception.py", line 181, in handle_uncaught_exception
    return debug.technical_500_response(request, *exc_info)
  File "/home/dgfsmg/virtualenv/repositories/dgfs_back/3.10/lib/python3.10/site-packages/django/views/debug.py", line 67, in technical_500_response
    html = reporter.get_traceback_html()
  File "/home/dgfsmg/virtualenv/repositories/dgfs_back/3.10/lib/python3.10/site-packages/django/views/debug.py", line 410, in get_traceback_html
    c = Context(self.get_traceback_data(), use_l10n=False)
  File "/home/dgfsmg/virtualenv/repositories/dgfs_back/3.10/lib/python3.10/site-packages/django/views/debug.py", line 393, in get_traceback_data
    c["raising_view_name"] = get_caller(self.request)
  File "/home/dgfsmg/virtualenv/repositories/dgfs_back/3.10/lib/python3.10/site-packages/django/views/debug.py", line 100, in get_caller
    resolver_match = resolve(request.path)
  File "/home/dgfsmg/virtualenv/repositories/dgfs_back/3.10/lib/python3.10/site-packages/django/urls/base.py", line 24, in resolve
    return get_resolver(urlconf).resolve(path)
  File "/home/dgfsmg/virtualenv/repositories/dgfs_back/3.10/lib/python3.10/site-packages/django/urls/resolvers.py", line 663, in resolve
    for pattern in self.url_patterns:
  File "/home/dgfsmg/virtualenv/repositories/dgfs_back/3.10/lib/python3.10/site-packages/django/utils/functional.py", line 57, in __get__
    res = instance.__dict__[self.name] = self.func(instance)
  File "/home/dgfsmg/virtualenv/repositories/dgfs_back/3.10/lib/python3.10/site-packages/django/urls/resolvers.py", line 715, in url_patterns
    patterns = getattr(self.urlconf_module, "urlpatterns", self.urlconf_module)
  File "/home/dgfsmg/virtualenv/repositories/dgfs_back/3.10/lib/python3.10/site-packages/django/utils/functional.py", line 57, in __get__
    res = instance.__dict__[self.name] = self.func(instance)
  File "/home/dgfsmg/virtualenv/repositories/dgfs_back/3.10/lib/python3.10/site-packages/django/urls/resolvers.py", line 708, in urlconf_module
    return import_module(self.urlconf_name)
  File "/opt/alt/python310/lib64/python3.10/importlib/__init__.py", line 126, in import_module
    return _bootstrap._gcd_import(name[level:], package, level)
  File "<frozen importlib._bootstrap>", line 1050, in _gcd_import
  File "<frozen importlib._bootstrap>", line 1027, in _find_and_load
  File "<frozen importlib._bootstrap>", line 1006, in _find_and_load_unlocked
  File "<frozen importlib._bootstrap>", line 688, in _load_unlocked
  File "<frozen importlib._bootstrap_external>", line 879, in exec_module
  File "<frozen importlib._bootstrap_external>", line 1017, in get_code
  File "<frozen importlib._bootstrap_external>", line 947, in source_to_code
  File "<frozen importlib._bootstrap>", line 241, in _call_with_frames_removed
  File "/home/dgfsmg/repositories/dgfs_back/MainRoot/urls.py", line 29
    urlpatterns += static(settings.MEDIA_URL, document_root=settings.MEDIA_ROOT , staticfiles_urlpatterns())
                                                                                                           ^
SyntaxError: positional argument follows keyword argument

During handling of the above exception, another exception occurred:

Traceback (most recent call last):
  File "/home/dgfsmg/virtualenv/repositories/dgfs_back/3.10/lib/python3.10/site-packages/django/core/handlers/exception.py", line 55, in inner
    response = get_response(request)
  File "/home/dgfsmg/virtualenv/repositories/dgfs_back/3.10/lib/python3.10/site-packages/django/utils/deprecation.py", line 134, in __call__
    response = response or self.get_response(request)
  File "/home/dgfsmg/virtualenv/repositories/dgfs_back/3.10/lib/python3.10/site-packages/django/core/handlers/exception.py", line 57, in inner
    response = response_for_exception(request, exc)
  File "/home/dgfsmg/virtualenv/repositories/dgfs_back/3.10/lib/python3.10/site-packages/django/core/handlers/exception.py", line 140, in response_for_exception
    response = handle_uncaught_exception(
  File "/home/dgfsmg/virtualenv/repositories/dgfs_back/3.10/lib/python3.10/site-packages/django/core/handlers/exception.py", line 181, in handle_uncaught_exception
    return debug.technical_500_response(request, *exc_info)
  File "/home/dgfsmg/virtualenv/repositories/dgfs_back/3.10/lib/python3.10/site-packages/django/views/debug.py", line 67, in technical_500_response
    html = reporter.get_traceback_html()
  File "/home/dgfsmg/virtualenv/repositories/dgfs_back/3.10/lib/python3.10/site-packages/django/views/debug.py", line 410, in get_traceback_html
    c = Context(self.get_traceback_data(), use_l10n=False)
  File "/home/dgfsmg/virtualenv/repositories/dgfs_back/3.10/lib/python3.10/site-packages/django/views/debug.py", line 393, in get_traceback_data
    c["raising_view_name"] = get_caller(self.request)
  File "/home/dgfsmg/virtualenv/repositories/dgfs_back/3.10/lib/python3.10/site-packages/django/views/debug.py", line 100, in get_caller
    resolver_match = resolve(request.path)
  File "/home/dgfsmg/virtualenv/repositories/dgfs_back/3.10/lib/python3.10/site-packages/django/urls/base.py", line 24, in resolve
    return get_resolver(urlconf).resolve(path)
  File "/home/dgfsmg/virtualenv/repositories/dgfs_back/3.10/lib/python3.10/site-packages/django/urls/resolvers.py", line 663, in resolve
    for pattern in self.url_patterns:
  File "/home/dgfsmg/virtualenv/repositories/dgfs_back/3.10/lib/python3.10/site-packages/django/utils/functional.py", line 57, in __get__
    res = instance.__dict__[self.name] = self.func(instance)
  File "/home/dgfsmg/virtualenv/repositories/dgfs_back/3.10/lib/python3.10/site-packages/django/urls/resolvers.py", line 715, in url_patterns
    patterns = getattr(self.urlconf_module, "urlpatterns", self.urlconf_module)
  File "/home/dgfsmg/virtualenv/repositories/dgfs_back/3.10/lib/python3.10/site-packages/django/utils/functional.py", line 57, in __get__
    res = instance.__dict__[self.name] = self.func(instance)
  File "/home/dgfsmg/virtualenv/repositories/dgfs_back/3.10/lib/python3.10/site-packages/django/urls/resolvers.py", line 708, in urlconf_module
    return import_module(self.urlconf_name)
  File "/opt/alt/python310/lib64/python3.10/importlib/__init__.py", line 126, in import_module
    return _bootstrap._gcd_import(name[level:], package, level)
  File "<frozen importlib._bootstrap>", line 1050, in _gcd_import
  File "<frozen importlib._bootstrap>", line 1027, in _find_and_load
  File "<frozen importlib._bootstrap>", line 1006, in _find_and_load_unlocked
  File "<frozen importlib._bootstrap>", line 688, in _load_unlocked
  File "<frozen importlib._bootstrap_external>", line 879, in exec_module
  File "<frozen importlib._bootstrap_external>", line 1017, in get_code
  File "<frozen importlib._bootstrap_external>", line 947, in source_to_code
  File "<frozen importlib._bootstrap>", line 241, in _call_with_frames_removed
  File "/home/dgfsmg/repositories/dgfs_back/MainRoot/urls.py", line 29
    urlpatterns += static(settings.MEDIA_URL, document_root=settings.MEDIA_ROOT , staticfiles_urlpatterns())
                                                                                                           ^
SyntaxError: positional argument follows keyword argument

During handling of the above exception, another exception occurred:

Traceback (most recent call last):
  File "/home/dgfsmg/virtualenv/repositories/dgfs_back/3.10/lib/python3.10/site-packages/django/core/handlers/exception.py", line 55, in inner
    response = get_response(request)
  File "/home/dgfsmg/virtualenv/repositories/dgfs_back/3.10/lib/python3.10/site-packages/django/utils/deprecation.py", line 134, in __call__
    response = response or self.get_response(request)
  File "/home/dgfsmg/virtualenv/repositories/dgfs_back/3.10/lib/python3.10/site-packages/django/core/handlers/exception.py", line 57, in inner
    response = response_for_exception(request, exc)
  File "/home/dgfsmg/virtualenv/repositories/dgfs_back/3.10/lib/python3.10/site-packages/django/core/handlers/exception.py", line 140, in response_for_exception
    response = handle_uncaught_exception(
  File "/home/dgfsmg/virtualenv/repositories/dgfs_back/3.10/lib/python3.10/site-packages/django/core/handlers/exception.py", line 181, in handle_uncaught_exception
    return debug.technical_500_response(request, *exc_info)
  File "/home/dgfsmg/virtualenv/repositories/dgfs_back/3.10/lib/python3.10/site-packages/django/views/debug.py", line 67, in technical_500_response
    html = reporter.get_traceback_html()
  File "/home/dgfsmg/virtualenv/repositories/dgfs_back/3.10/lib/python3.10/site-packages/django/views/debug.py", line 410, in get_traceback_html
    c = Context(self.get_traceback_data(), use_l10n=False)
  File "/home/dgfsmg/virtualenv/repositories/dgfs_back/3.10/lib/python3.10/site-packages/django/views/debug.py", line 393, in get_traceback_data
    c["raising_view_name"] = get_caller(self.request)
  File "/home/dgfsmg/virtualenv/repositories/dgfs_back/3.10/lib/python3.10/site-packages/django/views/debug.py", line 100, in get_caller
    resolver_match = resolve(request.path)
  File "/home/dgfsmg/virtualenv/repositories/dgfs_back/3.10/lib/python3.10/site-packages/django/urls/base.py", line 24, in resolve
    return get_resolver(urlconf).resolve(path)
  File "/home/dgfsmg/virtualenv/repositories/dgfs_back/3.10/lib/python3.10/site-packages/django/urls/resolvers.py", line 663, in resolve
    for pattern in self.url_patterns:
  File "/home/dgfsmg/virtualenv/repositories/dgfs_back/3.10/lib/python3.10/site-packages/django/utils/functional.py", line 57, in __get__
    res = instance.__dict__[self.name] = self.func(instance)
  File "/home/dgfsmg/virtualenv/repositories/dgfs_back/3.10/lib/python3.10/site-packages/django/urls/resolvers.py", line 715, in url_patterns
    patterns = getattr(self.urlconf_module, "urlpatterns", self.urlconf_module)
  File "/home/dgfsmg/virtualenv/repositories/dgfs_back/3.10/lib/python3.10/site-packages/django/utils/functional.py", line 57, in __get__
    res = instance.__dict__[self.name] = self.func(instance)
  File "/home/dgfsmg/virtualenv/repositories/dgfs_back/3.10/lib/python3.10/site-packages/django/urls/resolvers.py", line 708, in urlconf_module
    return import_module(self.urlconf_name)
  File "/opt/alt/python310/lib64/python3.10/importlib/__init__.py", line 126, in import_module
    return _bootstrap._gcd_import(name[level:], package, level)
  File "<frozen importlib._bootstrap>", line 1050, in _gcd_import
  File "<frozen importlib._bootstrap>", line 1027, in _find_and_load
  File "<frozen importlib._bootstrap>", line 1006, in _find_and_load_unlocked
  File "<frozen importlib._bootstrap>", line 688, in _load_unlocked
  File "<frozen importlib._bootstrap_external>", line 879, in exec_module
  File "<frozen importlib._bootstrap_external>", line 1017, in get_code
  File "<frozen importlib._bootstrap_external>", line 947, in source_to_code
  File "<frozen importlib._bootstrap>", line 241, in _call_with_frames_removed
  File "/home/dgfsmg/repositories/dgfs_back/MainRoot/urls.py", line 29
    urlpatterns += static(settings.MEDIA_URL, document_root=settings.MEDIA_ROOT , staticfiles_urlpatterns())
                                                                                                           ^
SyntaxError: positional argument follows keyword argument

During handling of the above exception, another exception occurred:

Traceback (most recent call last):
  File "/home/dgfsmg/virtualenv/repositories/dgfs_back/3.10/lib/python3.10/site-packages/django/core/handlers/wsgi.py", line 134, in __call__
    response = self.get_response(request)
  File "/home/dgfsmg/virtualenv/repositories/dgfs_back/3.10/lib/python3.10/site-packages/django/core/handlers/base.py", line 140, in get_response
    response = self._middleware_chain(request)
  File "/home/dgfsmg/virtualenv/repositories/dgfs_back/3.10/lib/python3.10/site-packages/django/core/handlers/exception.py", line 57, in inner
    response = response_for_exception(request, exc)
  File "/home/dgfsmg/virtualenv/repositories/dgfs_back/3.10/lib/python3.10/site-packages/django/core/handlers/exception.py", line 140, in response_for_exception
    response = handle_uncaught_exception(
  File "/home/dgfsmg/virtualenv/repositories/dgfs_back/3.10/lib/python3.10/site-packages/django/core/handlers/exception.py", line 181, in handle_uncaught_exception
    return debug.technical_500_response(request, *exc_info)
  File "/home/dgfsmg/virtualenv/repositories/dgfs_back/3.10/lib/python3.10/site-packages/django/views/debug.py", line 67, in technical_500_response
    html = reporter.get_traceback_html()
  File "/home/dgfsmg/virtualenv/repositories/dgfs_back/3.10/lib/python3.10/site-packages/django/views/debug.py", line 410, in get_traceback_html
    c = Context(self.get_traceback_data(), use_l10n=False)
  File "/home/dgfsmg/virtualenv/repositories/dgfs_back/3.10/lib/python3.10/site-packages/django/views/debug.py", line 393, in get_traceback_data
    c["raising_view_name"] = get_caller(self.request)
  File "/home/dgfsmg/virtualenv/repositories/dgfs_back/3.10/lib/python3.10/site-packages/django/views/debug.py", line 100, in get_caller
    resolver_match = resolve(request.path)
  File "/home/dgfsmg/virtualenv/repositories/dgfs_back/3.10/lib/python3.10/site-packages/django/urls/base.py", line 24, in resolve
    return get_resolver(urlconf).resolve(path)
  File "/home/dgfsmg/virtualenv/repositories/dgfs_back/3.10/lib/python3.10/site-packages/django/urls/resolvers.py", line 663, in resolve
    for pattern in self.url_patterns:
  File "/home/dgfsmg/virtualenv/repositories/dgfs_back/3.10/lib/python3.10/site-packages/django/utils/functional.py", line 57, in __get__
    res = instance.__dict__[self.name] = self.func(instance)
  File "/home/dgfsmg/virtualenv/repositories/dgfs_back/3.10/lib/python3.10/site-packages/django/urls/resolvers.py", line 715, in url_patterns
    patterns = getattr(self.urlconf_module, "urlpatterns", self.urlconf_module)
  File "/home/dgfsmg/virtualenv/repositories/dgfs_back/3.10/lib/python3.10/site-packages/django/utils/functional.py", line 57, in __get__
    res = instance.__dict__[self.name] = self.func(instance)
  File "/home/dgfsmg/virtualenv/repositories/dgfs_back/3.10/lib/python3.10/site-packages/django/urls/resolvers.py", line 708, in urlconf_module
    return import_module(self.urlconf_name)
  File "/opt/alt/python310/lib64/python3.10/importlib/__init__.py", line 126, in import_module
    return _bootstrap._gcd_import(name[level:], package, level)
  File "<frozen importlib._bootstrap>", line 1050, in _gcd_import
  File "<frozen importlib._bootstrap>", line 1027, in _find_and_load
  File "<frozen importlib._bootstrap>", line 1006, in _find_and_load_unlocked
  File "<frozen importlib._bootstrap>", line 688, in _load_unlocked
  File "<frozen importlib._bootstrap_external>", line 879, in exec_module
  File "<frozen importlib._bootstrap_external>", line 1017, in get_code
  File "<frozen importlib._bootstrap_external>", line 947, in source_to_code
  File "<frozen importlib._bootstrap>", line 241, in _call_with_frames_removed
  File "/home/dgfsmg/repositories/dgfs_back/MainRoot/urls.py", line 29
    urlpatterns += static(settings.MEDIA_URL, document_root=settings.MEDIA_ROOT , staticfiles_urlpatterns())
                                                                                                           ^
SyntaxError: positional argument follows keyword argument
[ERROR] [UID:3250][2542529] wsgiAppHandler pApp->start_response() return NULL.
Traceback (most recent call last):
  File "/home/dgfsmg/virtualenv/repositories/dgfs_back/3.10/lib/python3.10/site-packages/django/core/handlers/exception.py", line 55, in inner
    response = get_response(request)
  File "/home/dgfsmg/virtualenv/repositories/dgfs_back/3.10/lib/python3.10/site-packages/django/core/handlers/base.py", line 181, in _get_response
    callback, callback_args, callback_kwargs = self.resolve_request(request)
  File "/home/dgfsmg/virtualenv/repositories/dgfs_back/3.10/lib/python3.10/site-packages/django/core/handlers/base.py", line 313, in resolve_request
    resolver_match = resolver.resolve(request.path_info)
  File "/home/dgfsmg/virtualenv/repositories/dgfs_back/3.10/lib/python3.10/site-packages/django/urls/resolvers.py", line 663, in resolve
    for pattern in self.url_patterns:
  File "/home/dgfsmg/virtualenv/repositories/dgfs_back/3.10/lib/python3.10/site-packages/django/utils/functional.py", line 57, in __get__
    res = instance.__dict__[self.name] = self.func(instance)
  File "/home/dgfsmg/virtualenv/repositories/dgfs_back/3.10/lib/python3.10/site-packages/django/urls/resolvers.py", line 715, in url_patterns
    patterns = getattr(self.urlconf_module, "urlpatterns", self.urlconf_module)
  File "/home/dgfsmg/virtualenv/repositories/dgfs_back/3.10/lib/python3.10/site-packages/django/utils/functional.py", line 57, in __get__
    res = instance.__dict__[self.name] = self.func(instance)
  File "/home/dgfsmg/virtualenv/repositories/dgfs_back/3.10/lib/python3.10/site-packages/django/urls/resolvers.py", line 708, in urlconf_module
    return import_module(self.urlconf_name)
  File "/opt/alt/python310/lib64/python3.10/importlib/__init__.py", line 126, in import_module
    return _bootstrap._gcd_import(name[level:], package, level)
  File "<frozen importlib._bootstrap>", line 1050, in _gcd_import
  File "<frozen importlib._bootstrap>", line 1027, in _find_and_load
  File "<frozen importlib._bootstrap>", line 1006, in _find_and_load_unlocked
  File "<frozen importlib._bootstrap>", line 688, in _load_unlocked
  File "<frozen importlib._bootstrap_external>", line 879, in exec_module
  File "<frozen importlib._bootstrap_external>", line 1017, in get_code
  File "<frozen importlib._bootstrap_external>", line 947, in source_to_code
  File "<frozen importlib._bootstrap>", line 241, in _call_with_frames_removed
  File "/home/dgfsmg/repositories/dgfs_back/MainRoot/urls.py", line 29
    urlpatterns += static(settings.MEDIA_URL, document_root=settings.MEDIA_ROOT , staticfiles_urlpatterns())
                                                                                                           ^
SyntaxError: positional argument follows keyword argument

During handling of the above exception, another exception occurred:

Traceback (most recent call last):
  File "/home/dgfsmg/virtualenv/repositories/dgfs_back/3.10/lib/python3.10/site-packages/django/core/handlers/exception.py", line 55, in inner
    response = get_response(request)
  File "/home/dgfsmg/virtualenv/repositories/dgfs_back/3.10/lib/python3.10/site-packages/django/utils/deprecation.py", line 134, in __call__
    response = response or self.get_response(request)
  File "/home/dgfsmg/virtualenv/repositories/dgfs_back/3.10/lib/python3.10/site-packages/django/core/handlers/exception.py", line 57, in inner
    response = response_for_exception(request, exc)
  File "/home/dgfsmg/virtualenv/repositories/dgfs_back/3.10/lib/python3.10/site-packages/django/core/handlers/exception.py", line 140, in response_for_exception
    response = handle_uncaught_exception(
  File "/home/dgfsmg/virtualenv/repositories/dgfs_back/3.10/lib/python3.10/site-packages/django/core/handlers/exception.py", line 181, in handle_uncaught_exception
    return debug.technical_500_response(request, *exc_info)
  File "/home/dgfsmg/virtualenv/repositories/dgfs_back/3.10/lib/python3.10/site-packages/django/views/debug.py", line 67, in technical_500_response
    html = reporter.get_traceback_html()
  File "/home/dgfsmg/virtualenv/repositories/dgfs_back/3.10/lib/python3.10/site-packages/django/views/debug.py", line 410, in get_traceback_html
    c = Context(self.get_traceback_data(), use_l10n=False)
  File "/home/dgfsmg/virtualenv/repositories/dgfs_back/3.10/lib/python3.10/site-packages/django/views/debug.py", line 393, in get_traceback_data
    c["raising_view_name"] = get_caller(self.request)
  File "/home/dgfsmg/virtualenv/repositories/dgfs_back/3.10/lib/python3.10/site-packages/django/views/debug.py", line 100, in get_caller
    resolver_match = resolve(request.path)
  File "/home/dgfsmg/virtualenv/repositories/dgfs_back/3.10/lib/python3.10/site-packages/django/urls/base.py", line 24, in resolve
    return get_resolver(urlconf).resolve(path)
  File "/home/dgfsmg/virtualenv/repositories/dgfs_back/3.10/lib/python3.10/site-packages/django/urls/resolvers.py", line 663, in resolve
    for pattern in self.url_patterns:
  File "/home/dgfsmg/virtualenv/repositories/dgfs_back/3.10/lib/python3.10/site-packages/django/utils/functional.py", line 57, in __get__
    res = instance.__dict__[self.name] = self.func(instance)
  File "/home/dgfsmg/virtualenv/repositories/dgfs_back/3.10/lib/python3.10/site-packages/django/urls/resolvers.py", line 715, in url_patterns
    patterns = getattr(self.urlconf_module, "urlpatterns", self.urlconf_module)
  File "/home/dgfsmg/virtualenv/repositories/dgfs_back/3.10/lib/python3.10/site-packages/django/utils/functional.py", line 57, in __get__
    res = instance.__dict__[self.name] = self.func(instance)
  File "/home/dgfsmg/virtualenv/repositories/dgfs_back/3.10/lib/python3.10/site-packages/django/urls/resolvers.py", line 708, in urlconf_module
    return import_module(self.urlconf_name)
  File "/opt/alt/python310/lib64/python3.10/importlib/__init__.py", line 126, in import_module
    return _bootstrap._gcd_import(name[level:], package, level)
  File "<frozen importlib._bootstrap>", line 1050, in _gcd_import
  File "<frozen importlib._bootstrap>", line 1027, in _find_and_load
  File "<frozen importlib._bootstrap>", line 1006, in _find_and_load_unlocked
  File "<frozen importlib._bootstrap>", line 688, in _load_unlocked
  File "<frozen importlib._bootstrap_external>", line 879, in exec_module
  File "<frozen importlib._bootstrap_external>", line 1017, in get_code
  File "<frozen importlib._bootstrap_external>", line 947, in source_to_code
  File "<frozen importlib._bootstrap>", line 241, in _call_with_frames_removed
  File "/home/dgfsmg/repositories/dgfs_back/MainRoot/urls.py", line 29
    urlpatterns += static(settings.MEDIA_URL, document_root=settings.MEDIA_ROOT , staticfiles_urlpatterns())
                                                                                                           ^
SyntaxError: positional argument follows keyword argument

During handling of the above exception, another exception occurred:

Traceback (most recent call last):
  File "/home/dgfsmg/virtualenv/repositories/dgfs_back/3.10/lib/python3.10/site-packages/django/core/handlers/exception.py", line 55, in inner
    response = get_response(request)
  File "/home/dgfsmg/virtualenv/repositories/dgfs_back/3.10/lib/python3.10/site-packages/django/utils/deprecation.py", line 134, in __call__
    response = response or self.get_response(request)
  File "/home/dgfsmg/virtualenv/repositories/dgfs_back/3.10/lib/python3.10/site-packages/django/core/handlers/exception.py", line 57, in inner
    response = response_for_exception(request, exc)
  File "/home/dgfsmg/virtualenv/repositories/dgfs_back/3.10/lib/python3.10/site-packages/django/core/handlers/exception.py", line 140, in response_for_exception
    response = handle_uncaught_exception(
  File "/home/dgfsmg/virtualenv/repositories/dgfs_back/3.10/lib/python3.10/site-packages/django/core/handlers/exception.py", line 181, in handle_uncaught_exception
    return debug.technical_500_response(request, *exc_info)
  File "/home/dgfsmg/virtualenv/repositories/dgfs_back/3.10/lib/python3.10/site-packages/django/views/debug.py", line 67, in technical_500_response
    html = reporter.get_traceback_html()
  File "/home/dgfsmg/virtualenv/repositories/dgfs_back/3.10/lib/python3.10/site-packages/django/views/debug.py", line 410, in get_traceback_html
    c = Context(self.get_traceback_data(), use_l10n=False)
  File "/home/dgfsmg/virtualenv/repositories/dgfs_back/3.10/lib/python3.10/site-packages/django/views/debug.py", line 393, in get_traceback_data
    c["raising_view_name"] = get_caller(self.request)
  File "/home/dgfsmg/virtualenv/repositories/dgfs_back/3.10/lib/python3.10/site-packages/django/views/debug.py", line 100, in get_caller
    resolver_match = resolve(request.path)
  File "/home/dgfsmg/virtualenv/repositories/dgfs_back/3.10/lib/python3.10/site-packages/django/urls/base.py", line 24, in resolve
    return get_resolver(urlconf).resolve(path)
  File "/home/dgfsmg/virtualenv/repositories/dgfs_back/3.10/lib/python3.10/site-packages/django/urls/resolvers.py", line 663, in resolve
    for pattern in self.url_patterns:
  File "/home/dgfsmg/virtualenv/repositories/dgfs_back/3.10/lib/python3.10/site-packages/django/utils/functional.py", line 57, in __get__
    res = instance.__dict__[self.name] = self.func(instance)
  File "/home/dgfsmg/virtualenv/repositories/dgfs_back/3.10/lib/python3.10/site-packages/django/urls/resolvers.py", line 715, in url_patterns
    patterns = getattr(self.urlconf_module, "urlpatterns", self.urlconf_module)
  File "/home/dgfsmg/virtualenv/repositories/dgfs_back/3.10/lib/python3.10/site-packages/django/utils/functional.py", line 57, in __get__
    res = instance.__dict__[self.name] = self.func(instance)
  File "/home/dgfsmg/virtualenv/repositories/dgfs_back/3.10/lib/python3.10/site-packages/django/urls/resolvers.py", line 708, in urlconf_module
    return import_module(self.urlconf_name)
  File "/opt/alt/python310/lib64/python3.10/importlib/__init__.py", line 126, in import_module
    return _bootstrap._gcd_import(name[level:], package, level)
  File "<frozen importlib._bootstrap>", line 1050, in _gcd_import
  File "<frozen importlib._bootstrap>", line 1027, in _find_and_load
  File "<frozen importlib._bootstrap>", line 1006, in _find_and_load_unlocked
  File "<frozen importlib._bootstrap>", line 688, in _load_unlocked
  File "<frozen importlib._bootstrap_external>", line 879, in exec_module
  File "<frozen importlib._bootstrap_external>", line 1017, in get_code
  File "<frozen importlib._bootstrap_external>", line 947, in source_to_code
  File "<frozen importlib._bootstrap>", line 241, in _call_with_frames_removed
  File "/home/dgfsmg/repositories/dgfs_back/MainRoot/urls.py", line 29
    urlpatterns += static(settings.MEDIA_URL, document_root=settings.MEDIA_ROOT , staticfiles_urlpatterns())
                                                                                                           ^
SyntaxError: positional argument follows keyword argument

During handling of the above exception, another exception occurred:

Traceback (most recent call last):
  File "/home/dgfsmg/virtualenv/repositories/dgfs_back/3.10/lib/python3.10/site-packages/django/core/handlers/exception.py", line 55, in inner
    response = get_response(request)
  File "/home/dgfsmg/virtualenv/repositories/dgfs_back/3.10/lib/python3.10/site-packages/django/utils/deprecation.py", line 134, in __call__
    response = response or self.get_response(request)
  File "/home/dgfsmg/virtualenv/repositories/dgfs_back/3.10/lib/python3.10/site-packages/django/core/handlers/exception.py", line 57, in inner
    response = response_for_exception(request, exc)
  File "/home/dgfsmg/virtualenv/repositories/dgfs_back/3.10/lib/python3.10/site-packages/django/core/handlers/exception.py", line 140, in response_for_exception
    response = handle_uncaught_exception(
  File "/home/dgfsmg/virtualenv/repositories/dgfs_back/3.10/lib/python3.10/site-packages/django/core/handlers/exception.py", line 181, in handle_uncaught_exception
    return debug.technical_500_response(request, *exc_info)
  File "/home/dgfsmg/virtualenv/repositories/dgfs_back/3.10/lib/python3.10/site-packages/django/views/debug.py", line 67, in technical_500_response
    html = reporter.get_traceback_html()
  File "/home/dgfsmg/virtualenv/repositories/dgfs_back/3.10/lib/python3.10/site-packages/django/views/debug.py", line 410, in get_traceback_html
    c = Context(self.get_traceback_data(), use_l10n=False)
  File "/home/dgfsmg/virtualenv/repositories/dgfs_back/3.10/lib/python3.10/site-packages/django/views/debug.py", line 393, in get_traceback_data
    c["raising_view_name"] = get_caller(self.request)
  File "/home/dgfsmg/virtualenv/repositories/dgfs_back/3.10/lib/python3.10/site-packages/django/views/debug.py", line 100, in get_caller
    resolver_match = resolve(request.path)
  File "/home/dgfsmg/virtualenv/repositories/dgfs_back/3.10/lib/python3.10/site-packages/django/urls/base.py", line 24, in resolve
    return get_resolver(urlconf).resolve(path)
  File "/home/dgfsmg/virtualenv/repositories/dgfs_back/3.10/lib/python3.10/site-packages/django/urls/resolvers.py", line 663, in resolve
    for pattern in self.url_patterns:
  File "/home/dgfsmg/virtualenv/repositories/dgfs_back/3.10/lib/python3.10/site-packages/django/utils/functional.py", line 57, in __get__
    res = instance.__dict__[self.name] = self.func(instance)
  File "/home/dgfsmg/virtualenv/repositories/dgfs_back/3.10/lib/python3.10/site-packages/django/urls/resolvers.py", line 715, in url_patterns
    patterns = getattr(self.urlconf_module, "urlpatterns", self.urlconf_module)
  File "/home/dgfsmg/virtualenv/repositories/dgfs_back/3.10/lib/python3.10/site-packages/django/utils/functional.py", line 57, in __get__
    res = instance.__dict__[self.name] = self.func(instance)
  File "/home/dgfsmg/virtualenv/repositories/dgfs_back/3.10/lib/python3.10/site-packages/django/urls/resolvers.py", line 708, in urlconf_module
    return import_module(self.urlconf_name)
  File "/opt/alt/python310/lib64/python3.10/importlib/__init__.py", line 126, in import_module
    return _bootstrap._gcd_import(name[level:], package, level)
  File "<frozen importlib._bootstrap>", line 1050, in _gcd_import
  File "<frozen importlib._bootstrap>", line 1027, in _find_and_load
  File "<frozen importlib._bootstrap>", line 1006, in _find_and_load_unlocked
  File "<frozen importlib._bootstrap>", line 688, in _load_unlocked
  File "<frozen importlib._bootstrap_external>", line 879, in exec_module
  File "<frozen importlib._bootstrap_external>", line 1017, in get_code
  File "<frozen importlib._bootstrap_external>", line 947, in source_to_code
  File "<frozen importlib._bootstrap>", line 241, in _call_with_frames_removed
  File "/home/dgfsmg/repositories/dgfs_back/MainRoot/urls.py", line 29
    urlpatterns += static(settings.MEDIA_URL, document_root=settings.MEDIA_ROOT , staticfiles_urlpatterns())
                                                                                                           ^
SyntaxError: positional argument follows keyword argument

During handling of the above exception, another exception occurred:

Traceback (most recent call last):
  File "/home/dgfsmg/virtualenv/repositories/dgfs_back/3.10/lib/python3.10/site-packages/django/core/handlers/exception.py", line 55, in inner
    response = get_response(request)
  File "/home/dgfsmg/virtualenv/repositories/dgfs_back/3.10/lib/python3.10/site-packages/django/utils/deprecation.py", line 134, in __call__
    response = response or self.get_response(request)
  File "/home/dgfsmg/virtualenv/repositories/dgfs_back/3.10/lib/python3.10/site-packages/django/core/handlers/exception.py", line 57, in inner
    response = response_for_exception(request, exc)
  File "/home/dgfsmg/virtualenv/repositories/dgfs_back/3.10/lib/python3.10/site-packages/django/core/handlers/exception.py", line 140, in response_for_exception
    response = handle_uncaught_exception(
  File "/home/dgfsmg/virtualenv/repositories/dgfs_back/3.10/lib/python3.10/site-packages/django/core/handlers/exception.py", line 181, in handle_uncaught_exception
    return debug.technical_500_response(request, *exc_info)
  File "/home/dgfsmg/virtualenv/repositories/dgfs_back/3.10/lib/python3.10/site-packages/django/views/debug.py", line 67, in technical_500_response
    html = reporter.get_traceback_html()
  File "/home/dgfsmg/virtualenv/repositories/dgfs_back/3.10/lib/python3.10/site-packages/django/views/debug.py", line 410, in get_traceback_html
    c = Context(self.get_traceback_data(), use_l10n=False)
  File "/home/dgfsmg/virtualenv/repositories/dgfs_back/3.10/lib/python3.10/site-packages/django/views/debug.py", line 393, in get_traceback_data
    c["raising_view_name"] = get_caller(self.request)
  File "/home/dgfsmg/virtualenv/repositories/dgfs_back/3.10/lib/python3.10/site-packages/django/views/debug.py", line 100, in get_caller
    resolver_match = resolve(request.path)
  File "/home/dgfsmg/virtualenv/repositories/dgfs_back/3.10/lib/python3.10/site-packages/django/urls/base.py", line 24, in resolve
    return get_resolver(urlconf).resolve(path)
  File "/home/dgfsmg/virtualenv/repositories/dgfs_back/3.10/lib/python3.10/site-packages/django/urls/resolvers.py", line 663, in resolve
    for pattern in self.url_patterns:
  File "/home/dgfsmg/virtualenv/repositories/dgfs_back/3.10/lib/python3.10/site-packages/django/utils/functional.py", line 57, in __get__
    res = instance.__dict__[self.name] = self.func(instance)
  File "/home/dgfsmg/virtualenv/repositories/dgfs_back/3.10/lib/python3.10/site-packages/django/urls/resolvers.py", line 715, in url_patterns
    patterns = getattr(self.urlconf_module, "urlpatterns", self.urlconf_module)
  File "/home/dgfsmg/virtualenv/repositories/dgfs_back/3.10/lib/python3.10/site-packages/django/utils/functional.py", line 57, in __get__
    res = instance.__dict__[self.name] = self.func(instance)
  File "/home/dgfsmg/virtualenv/repositories/dgfs_back/3.10/lib/python3.10/site-packages/django/urls/resolvers.py", line 708, in urlconf_module
    return import_module(self.urlconf_name)
  File "/opt/alt/python310/lib64/python3.10/importlib/__init__.py", line 126, in import_module
    return _bootstrap._gcd_import(name[level:], package, level)
  File "<frozen importlib._bootstrap>", line 1050, in _gcd_import
  File "<frozen importlib._bootstrap>", line 1027, in _find_and_load
  File "<frozen importlib._bootstrap>", line 1006, in _find_and_load_unlocked
  File "<frozen importlib._bootstrap>", line 688, in _load_unlocked
  File "<frozen importlib._bootstrap_external>", line 879, in exec_module
  File "<frozen importlib._bootstrap_external>", line 1017, in get_code
  File "<frozen importlib._bootstrap_external>", line 947, in source_to_code
  File "<frozen importlib._bootstrap>", line 241, in _call_with_frames_removed
  File "/home/dgfsmg/repositories/dgfs_back/MainRoot/urls.py", line 29
    urlpatterns += static(settings.MEDIA_URL, document_root=settings.MEDIA_ROOT , staticfiles_urlpatterns())
                                                                                                           ^
SyntaxError: positional argument follows keyword argument

During handling of the above exception, another exception occurred:

Traceback (most recent call last):
  File "/home/dgfsmg/virtualenv/repositories/dgfs_back/3.10/lib/python3.10/site-packages/django/core/handlers/exception.py", line 55, in inner
    response = get_response(request)
  File "/home/dgfsmg/virtualenv/repositories/dgfs_back/3.10/lib/python3.10/site-packages/django/utils/deprecation.py", line 134, in __call__
    response = response or self.get_response(request)
  File "/home/dgfsmg/virtualenv/repositories/dgfs_back/3.10/lib/python3.10/site-packages/django/core/handlers/exception.py", line 57, in inner
    response = response_for_exception(request, exc)
  File "/home/dgfsmg/virtualenv/repositories/dgfs_back/3.10/lib/python3.10/site-packages/django/core/handlers/exception.py", line 140, in response_for_exception
    response = handle_uncaught_exception(
  File "/home/dgfsmg/virtualenv/repositories/dgfs_back/3.10/lib/python3.10/site-packages/django/core/handlers/exception.py", line 181, in handle_uncaught_exception
    return debug.technical_500_response(request, *exc_info)
  File "/home/dgfsmg/virtualenv/repositories/dgfs_back/3.10/lib/python3.10/site-packages/django/views/debug.py", line 67, in technical_500_response
    html = reporter.get_traceback_html()
  File "/home/dgfsmg/virtualenv/repositories/dgfs_back/3.10/lib/python3.10/site-packages/django/views/debug.py", line 410, in get_traceback_html
    c = Context(self.get_traceback_data(), use_l10n=False)
  File "/home/dgfsmg/virtualenv/repositories/dgfs_back/3.10/lib/python3.10/site-packages/django/views/debug.py", line 393, in get_traceback_data
    c["raising_view_name"] = get_caller(self.request)
  File "/home/dgfsmg/virtualenv/repositories/dgfs_back/3.10/lib/python3.10/site-packages/django/views/debug.py", line 100, in get_caller
    resolver_match = resolve(request.path)
  File "/home/dgfsmg/virtualenv/repositories/dgfs_back/3.10/lib/python3.10/site-packages/django/urls/base.py", line 24, in resolve
    return get_resolver(urlconf).resolve(path)
  File "/home/dgfsmg/virtualenv/repositories/dgfs_back/3.10/lib/python3.10/site-packages/django/urls/resolvers.py", line 663, in resolve
    for pattern in self.url_patterns:
  File "/home/dgfsmg/virtualenv/repositories/dgfs_back/3.10/lib/python3.10/site-packages/django/utils/functional.py", line 57, in __get__
    res = instance.__dict__[self.name] = self.func(instance)
  File "/home/dgfsmg/virtualenv/repositories/dgfs_back/3.10/lib/python3.10/site-packages/django/urls/resolvers.py", line 715, in url_patterns
    patterns = getattr(self.urlconf_module, "urlpatterns", self.urlconf_module)
  File "/home/dgfsmg/virtualenv/repositories/dgfs_back/3.10/lib/python3.10/site-packages/django/utils/functional.py", line 57, in __get__
    res = instance.__dict__[self.name] = self.func(instance)
  File "/home/dgfsmg/virtualenv/repositories/dgfs_back/3.10/lib/python3.10/site-packages/django/urls/resolvers.py", line 708, in urlconf_module
    return import_module(self.urlconf_name)
  File "/opt/alt/python310/lib64/python3.10/importlib/__init__.py", line 126, in import_module
    return _bootstrap._gcd_import(name[level:], package, level)
  File "<frozen importlib._bootstrap>", line 1050, in _gcd_import
  File "<frozen importlib._bootstrap>", line 1027, in _find_and_load
  File "<frozen importlib._bootstrap>", line 1006, in _find_and_load_unlocked
  File "<frozen importlib._bootstrap>", line 688, in _load_unlocked
  File "<frozen importlib._bootstrap_external>", line 879, in exec_module
  File "<frozen importlib._bootstrap_external>", line 1017, in get_code
  File "<frozen importlib._bootstrap_external>", line 947, in source_to_code
  File "<frozen importlib._bootstrap>", line 241, in _call_with_frames_removed
  File "/home/dgfsmg/repositories/dgfs_back/MainRoot/urls.py", line 29
    urlpatterns += static(settings.MEDIA_URL, document_root=settings.MEDIA_ROOT , staticfiles_urlpatterns())
                                                                                                           ^
SyntaxError: positional argument follows keyword argument

During handling of the above exception, another exception occurred:

Traceback (most recent call last):
  File "/home/dgfsmg/virtualenv/repositories/dgfs_back/3.10/lib/python3.10/site-packages/django/core/handlers/exception.py", line 55, in inner
    response = get_response(request)
  File "/home/dgfsmg/virtualenv/repositories/dgfs_back/3.10/lib/python3.10/site-packages/django/utils/deprecation.py", line 134, in __call__
    response = response or self.get_response(request)
  File "/home/dgfsmg/virtualenv/repositories/dgfs_back/3.10/lib/python3.10/site-packages/django/core/handlers/exception.py", line 57, in inner
    response = response_for_exception(request, exc)
  File "/home/dgfsmg/virtualenv/repositories/dgfs_back/3.10/lib/python3.10/site-packages/django/core/handlers/exception.py", line 140, in response_for_exception
    response = handle_uncaught_exception(
  File "/home/dgfsmg/virtualenv/repositories/dgfs_back/3.10/lib/python3.10/site-packages/django/core/handlers/exception.py", line 181, in handle_uncaught_exception
    return debug.technical_500_response(request, *exc_info)
  File "/home/dgfsmg/virtualenv/repositories/dgfs_back/3.10/lib/python3.10/site-packages/django/views/debug.py", line 67, in technical_500_response
    html = reporter.get_traceback_html()
  File "/home/dgfsmg/virtualenv/repositories/dgfs_back/3.10/lib/python3.10/site-packages/django/views/debug.py", line 410, in get_traceback_html
    c = Context(self.get_traceback_data(), use_l10n=False)
  File "/home/dgfsmg/virtualenv/repositories/dgfs_back/3.10/lib/python3.10/site-packages/django/views/debug.py", line 393, in get_traceback_data
    c["raising_view_name"] = get_caller(self.request)
  File "/home/dgfsmg/virtualenv/repositories/dgfs_back/3.10/lib/python3.10/site-packages/django/views/debug.py", line 100, in get_caller
    resolver_match = resolve(request.path)
  File "/home/dgfsmg/virtualenv/repositories/dgfs_back/3.10/lib/python3.10/site-packages/django/urls/base.py", line 24, in resolve
    return get_resolver(urlconf).resolve(path)
  File "/home/dgfsmg/virtualenv/repositories/dgfs_back/3.10/lib/python3.10/site-packages/django/urls/resolvers.py", line 663, in resolve
    for pattern in self.url_patterns:
  File "/home/dgfsmg/virtualenv/repositories/dgfs_back/3.10/lib/python3.10/site-packages/django/utils/functional.py", line 57, in __get__
    res = instance.__dict__[self.name] = self.func(instance)
  File "/home/dgfsmg/virtualenv/repositories/dgfs_back/3.10/lib/python3.10/site-packages/django/urls/resolvers.py", line 715, in url_patterns
    patterns = getattr(self.urlconf_module, "urlpatterns", self.urlconf_module)
  File "/home/dgfsmg/virtualenv/repositories/dgfs_back/3.10/lib/python3.10/site-packages/django/utils/functional.py", line 57, in __get__
    res = instance.__dict__[self.name] = self.func(instance)
  File "/home/dgfsmg/virtualenv/repositories/dgfs_back/3.10/lib/python3.10/site-packages/django/urls/resolvers.py", line 708, in urlconf_module
    return import_module(self.urlconf_name)
  File "/opt/alt/python310/lib64/python3.10/importlib/__init__.py", line 126, in import_module
    return _bootstrap._gcd_import(name[level:], package, level)
  File "<frozen importlib._bootstrap>", line 1050, in _gcd_import
  File "<frozen importlib._bootstrap>", line 1027, in _find_and_load
  File "<frozen importlib._bootstrap>", line 1006, in _find_and_load_unlocked
  File "<frozen importlib._bootstrap>", line 688, in _load_unlocked
  File "<frozen importlib._bootstrap_external>", line 879, in exec_module
  File "<frozen importlib._bootstrap_external>", line 1017, in get_code
  File "<frozen importlib._bootstrap_external>", line 947, in source_to_code
  File "<frozen importlib._bootstrap>", line 241, in _call_with_frames_removed
  File "/home/dgfsmg/repositories/dgfs_back/MainRoot/urls.py", line 29
    urlpatterns += static(settings.MEDIA_URL, document_root=settings.MEDIA_ROOT , staticfiles_urlpatterns())
                                                                                                           ^
SyntaxError: positional argument follows keyword argument

During handling of the above exception, another exception occurred:

Traceback (most recent call last):
  File "/home/dgfsmg/virtualenv/repositories/dgfs_back/3.10/lib/python3.10/site-packages/django/core/handlers/exception.py", line 55, in inner
    response = get_response(request)
  File "/home/dgfsmg/virtualenv/repositories/dgfs_back/3.10/lib/python3.10/site-packages/whitenoise/middleware.py", line 124, in __call__
    return self.get_response(request)
  File "/home/dgfsmg/virtualenv/repositories/dgfs_back/3.10/lib/python3.10/site-packages/django/core/handlers/exception.py", line 57, in inner
    response = response_for_exception(request, exc)
  File "/home/dgfsmg/virtualenv/repositories/dgfs_back/3.10/lib/python3.10/site-packages/django/core/handlers/exception.py", line 140, in response_for_exception
    response = handle_uncaught_exception(
  File "/home/dgfsmg/virtualenv/repositories/dgfs_back/3.10/lib/python3.10/site-packages/django/core/handlers/exception.py", line 181, in handle_uncaught_exception
    return debug.technical_500_response(request, *exc_info)
  File "/home/dgfsmg/virtualenv/repositories/dgfs_back/3.10/lib/python3.10/site-packages/django/views/debug.py", line 67, in technical_500_response
    html = reporter.get_traceback_html()
  File "/home/dgfsmg/virtualenv/repositories/dgfs_back/3.10/lib/python3.10/site-packages/django/views/debug.py", line 410, in get_traceback_html
    c = Context(self.get_traceback_data(), use_l10n=False)
  File "/home/dgfsmg/virtualenv/repositories/dgfs_back/3.10/lib/python3.10/site-packages/django/views/debug.py", line 393, in get_traceback_data
    c["raising_view_name"] = get_caller(self.request)
  File "/home/dgfsmg/virtualenv/repositories/dgfs_back/3.10/lib/python3.10/site-packages/django/views/debug.py", line 100, in get_caller
    resolver_match = resolve(request.path)
  File "/home/dgfsmg/virtualenv/repositories/dgfs_back/3.10/lib/python3.10/site-packages/django/urls/base.py", line 24, in resolve
    return get_resolver(urlconf).resolve(path)
  File "/home/dgfsmg/virtualenv/repositories/dgfs_back/3.10/lib/python3.10/site-packages/django/urls/resolvers.py", line 663, in resolve
    for pattern in self.url_patterns:
  File "/home/dgfsmg/virtualenv/repositories/dgfs_back/3.10/lib/python3.10/site-packages/django/utils/functional.py", line 57, in __get__
    res = instance.__dict__[self.name] = self.func(instance)
  File "/home/dgfsmg/virtualenv/repositories/dgfs_back/3.10/lib/python3.10/site-packages/django/urls/resolvers.py", line 715, in url_patterns
    patterns = getattr(self.urlconf_module, "urlpatterns", self.urlconf_module)
  File "/home/dgfsmg/virtualenv/repositories/dgfs_back/3.10/lib/python3.10/site-packages/django/utils/functional.py", line 57, in __get__
    res = instance.__dict__[self.name] = self.func(instance)
  File "/home/dgfsmg/virtualenv/repositories/dgfs_back/3.10/lib/python3.10/site-packages/django/urls/resolvers.py", line 708, in urlconf_module
    return import_module(self.urlconf_name)
  File "/opt/alt/python310/lib64/python3.10/importlib/__init__.py", line 126, in import_module
    return _bootstrap._gcd_import(name[level:], package, level)
  File "<frozen importlib._bootstrap>", line 1050, in _gcd_import
  File "<frozen importlib._bootstrap>", line 1027, in _find_and_load
  File "<frozen importlib._bootstrap>", line 1006, in _find_and_load_unlocked
  File "<frozen importlib._bootstrap>", line 688, in _load_unlocked
  File "<frozen importlib._bootstrap_external>", line 879, in exec_module
  File "<frozen importlib._bootstrap_external>", line 1017, in get_code
  File "<frozen importlib._bootstrap_external>", line 947, in source_to_code
  File "<frozen importlib._bootstrap>", line 241, in _call_with_frames_removed
  File "/home/dgfsmg/repositories/dgfs_back/MainRoot/urls.py", line 29
    urlpatterns += static(settings.MEDIA_URL, document_root=settings.MEDIA_ROOT , staticfiles_urlpatterns())
                                                                                                           ^
SyntaxError: positional argument follows keyword argument

During handling of the above exception, another exception occurred:

Traceback (most recent call last):
  File "/home/dgfsmg/virtualenv/repositories/dgfs_back/3.10/lib/python3.10/site-packages/django/core/handlers/exception.py", line 55, in inner
    response = get_response(request)
  File "/home/dgfsmg/virtualenv/repositories/dgfs_back/3.10/lib/python3.10/site-packages/django/utils/deprecation.py", line 134, in __call__
    response = response or self.get_response(request)
  File "/home/dgfsmg/virtualenv/repositories/dgfs_back/3.10/lib/python3.10/site-packages/django/core/handlers/exception.py", line 57, in inner
    response = response_for_exception(request, exc)
  File "/home/dgfsmg/virtualenv/repositories/dgfs_back/3.10/lib/python3.10/site-packages/django/core/handlers/exception.py", line 140, in response_for_exception
    response = handle_uncaught_exception(
  File "/home/dgfsmg/virtualenv/repositories/dgfs_back/3.10/lib/python3.10/site-packages/django/core/handlers/exception.py", line 181, in handle_uncaught_exception
    return debug.technical_500_response(request, *exc_info)
  File "/home/dgfsmg/virtualenv/repositories/dgfs_back/3.10/lib/python3.10/site-packages/django/views/debug.py", line 67, in technical_500_response
    html = reporter.get_traceback_html()
  File "/home/dgfsmg/virtualenv/repositories/dgfs_back/3.10/lib/python3.10/site-packages/django/views/debug.py", line 410, in get_traceback_html
    c = Context(self.get_traceback_data(), use_l10n=False)
  File "/home/dgfsmg/virtualenv/repositories/dgfs_back/3.10/lib/python3.10/site-packages/django/views/debug.py", line 393, in get_traceback_data
    c["raising_view_name"] = get_caller(self.request)
  File "/home/dgfsmg/virtualenv/repositories/dgfs_back/3.10/lib/python3.10/site-packages/django/views/debug.py", line 100, in get_caller
    resolver_match = resolve(request.path)
  File "/home/dgfsmg/virtualenv/repositories/dgfs_back/3.10/lib/python3.10/site-packages/django/urls/base.py", line 24, in resolve
    return get_resolver(urlconf).resolve(path)
  File "/home/dgfsmg/virtualenv/repositories/dgfs_back/3.10/lib/python3.10/site-packages/django/urls/resolvers.py", line 663, in resolve
    for pattern in self.url_patterns:
  File "/home/dgfsmg/virtualenv/repositories/dgfs_back/3.10/lib/python3.10/site-packages/django/utils/functional.py", line 57, in __get__
    res = instance.__dict__[self.name] = self.func(instance)
  File "/home/dgfsmg/virtualenv/repositories/dgfs_back/3.10/lib/python3.10/site-packages/django/urls/resolvers.py", line 715, in url_patterns
    patterns = getattr(self.urlconf_module, "urlpatterns", self.urlconf_module)
  File "/home/dgfsmg/virtualenv/repositories/dgfs_back/3.10/lib/python3.10/site-packages/django/utils/functional.py", line 57, in __get__
    res = instance.__dict__[self.name] = self.func(instance)
  File "/home/dgfsmg/virtualenv/repositories/dgfs_back/3.10/lib/python3.10/site-packages/django/urls/resolvers.py", line 708, in urlconf_module
    return import_module(self.urlconf_name)
  File "/opt/alt/python310/lib64/python3.10/importlib/__init__.py", line 126, in import_module
    return _bootstrap._gcd_import(name[level:], package, level)
  File "<frozen importlib._bootstrap>", line 1050, in _gcd_import
  File "<frozen importlib._bootstrap>", line 1027, in _find_and_load
  File "<frozen importlib._bootstrap>", line 1006, in _find_and_load_unlocked
  File "<frozen importlib._bootstrap>", line 688, in _load_unlocked
  File "<frozen importlib._bootstrap_external>", line 879, in exec_module
  File "<frozen importlib._bootstrap_external>", line 1017, in get_code
  File "<frozen importlib._bootstrap_external>", line 947, in source_to_code
  File "<frozen importlib._bootstrap>", line 241, in _call_with_frames_removed
  File "/home/dgfsmg/repositories/dgfs_back/MainRoot/urls.py", line 29
    urlpatterns += static(settings.MEDIA_URL, document_root=settings.MEDIA_ROOT , staticfiles_urlpatterns())
                                                                                                           ^
SyntaxError: positional argument follows keyword argument

During handling of the above exception, another exception occurred:

Traceback (most recent call last):
  File "/home/dgfsmg/virtualenv/repositories/dgfs_back/3.10/lib/python3.10/site-packages/django/core/handlers/exception.py", line 55, in inner
    response = get_response(request)
  File "/home/dgfsmg/virtualenv/repositories/dgfs_back/3.10/lib/python3.10/site-packages/django/utils/deprecation.py", line 134, in __call__
    response = response or self.get_response(request)
  File "/home/dgfsmg/virtualenv/repositories/dgfs_back/3.10/lib/python3.10/site-packages/django/core/handlers/exception.py", line 57, in inner
    response = response_for_exception(request, exc)
  File "/home/dgfsmg/virtualenv/repositories/dgfs_back/3.10/lib/python3.10/site-packages/django/core/handlers/exception.py", line 140, in response_for_exception
    response = handle_uncaught_exception(
  File "/home/dgfsmg/virtualenv/repositories/dgfs_back/3.10/lib/python3.10/site-packages/django/core/handlers/exception.py", line 181, in handle_uncaught_exception
    return debug.technical_500_response(request, *exc_info)
  File "/home/dgfsmg/virtualenv/repositories/dgfs_back/3.10/lib/python3.10/site-packages/django/views/debug.py", line 67, in technical_500_response
    html = reporter.get_traceback_html()
  File "/home/dgfsmg/virtualenv/repositories/dgfs_back/3.10/lib/python3.10/site-packages/django/views/debug.py", line 410, in get_traceback_html
    c = Context(self.get_traceback_data(), use_l10n=False)
  File "/home/dgfsmg/virtualenv/repositories/dgfs_back/3.10/lib/python3.10/site-packages/django/views/debug.py", line 393, in get_traceback_data
    c["raising_view_name"] = get_caller(self.request)
  File "/home/dgfsmg/virtualenv/repositories/dgfs_back/3.10/lib/python3.10/site-packages/django/views/debug.py", line 100, in get_caller
    resolver_match = resolve(request.path)
  File "/home/dgfsmg/virtualenv/repositories/dgfs_back/3.10/lib/python3.10/site-packages/django/urls/base.py", line 24, in resolve
    return get_resolver(urlconf).resolve(path)
  File "/home/dgfsmg/virtualenv/repositories/dgfs_back/3.10/lib/python3.10/site-packages/django/urls/resolvers.py", line 663, in resolve
    for pattern in self.url_patterns:
  File "/home/dgfsmg/virtualenv/repositories/dgfs_back/3.10/lib/python3.10/site-packages/django/utils/functional.py", line 57, in __get__
    res = instance.__dict__[self.name] = self.func(instance)
  File "/home/dgfsmg/virtualenv/repositories/dgfs_back/3.10/lib/python3.10/site-packages/django/urls/resolvers.py", line 715, in url_patterns
    patterns = getattr(self.urlconf_module, "urlpatterns", self.urlconf_module)
  File "/home/dgfsmg/virtualenv/repositories/dgfs_back/3.10/lib/python3.10/site-packages/django/utils/functional.py", line 57, in __get__
    res = instance.__dict__[self.name] = self.func(instance)
  File "/home/dgfsmg/virtualenv/repositories/dgfs_back/3.10/lib/python3.10/site-packages/django/urls/resolvers.py", line 708, in urlconf_module
    return import_module(self.urlconf_name)
  File "/opt/alt/python310/lib64/python3.10/importlib/__init__.py", line 126, in import_module
    return _bootstrap._gcd_import(name[level:], package, level)
  File "<frozen importlib._bootstrap>", line 1050, in _gcd_import
  File "<frozen importlib._bootstrap>", line 1027, in _find_and_load
  File "<frozen importlib._bootstrap>", line 1006, in _find_and_load_unlocked
  File "<frozen importlib._bootstrap>", line 688, in _load_unlocked
  File "<frozen importlib._bootstrap_external>", line 879, in exec_module
  File "<frozen importlib._bootstrap_external>", line 1017, in get_code
  File "<frozen importlib._bootstrap_external>", line 947, in source_to_code
  File "<frozen importlib._bootstrap>", line 241, in _call_with_frames_removed
  File "/home/dgfsmg/repositories/dgfs_back/MainRoot/urls.py", line 29
    urlpatterns += static(settings.MEDIA_URL, document_root=settings.MEDIA_ROOT , staticfiles_urlpatterns())
                                                                                                           ^
SyntaxError: positional argument follows keyword argument

During handling of the above exception, another exception occurred:

Traceback (most recent call last):
  File "/home/dgfsmg/virtualenv/repositories/dgfs_back/3.10/lib/python3.10/site-packages/django/core/handlers/wsgi.py", line 134, in __call__
    response = self.get_response(request)
  File "/home/dgfsmg/virtualenv/repositories/dgfs_back/3.10/lib/python3.10/site-packages/django/core/handlers/base.py", line 140, in get_response
    response = self._middleware_chain(request)
  File "/home/dgfsmg/virtualenv/repositories/dgfs_back/3.10/lib/python3.10/site-packages/django/core/handlers/exception.py", line 57, in inner
    response = response_for_exception(request, exc)
  File "/home/dgfsmg/virtualenv/repositories/dgfs_back/3.10/lib/python3.10/site-packages/django/core/handlers/exception.py", line 140, in response_for_exception
    response = handle_uncaught_exception(
  File "/home/dgfsmg/virtualenv/repositories/dgfs_back/3.10/lib/python3.10/site-packages/django/core/handlers/exception.py", line 181, in handle_uncaught_exception
    return debug.technical_500_response(request, *exc_info)
  File "/home/dgfsmg/virtualenv/repositories/dgfs_back/3.10/lib/python3.10/site-packages/django/views/debug.py", line 67, in technical_500_response
    html = reporter.get_traceback_html()
  File "/home/dgfsmg/virtualenv/repositories/dgfs_back/3.10/lib/python3.10/site-packages/django/views/debug.py", line 410, in get_traceback_html
    c = Context(self.get_traceback_data(), use_l10n=False)
  File "/home/dgfsmg/virtualenv/repositories/dgfs_back/3.10/lib/python3.10/site-packages/django/views/debug.py", line 393, in get_traceback_data
    c["raising_view_name"] = get_caller(self.request)
  File "/home/dgfsmg/virtualenv/repositories/dgfs_back/3.10/lib/python3.10/site-packages/django/views/debug.py", line 100, in get_caller
    resolver_match = resolve(request.path)
  File "/home/dgfsmg/virtualenv/repositories/dgfs_back/3.10/lib/python3.10/site-packages/django/urls/base.py", line 24, in resolve
    return get_resolver(urlconf).resolve(path)
  File "/home/dgfsmg/virtualenv/repositories/dgfs_back/3.10/lib/python3.10/site-packages/django/urls/resolvers.py", line 663, in resolve
    for pattern in self.url_patterns:
  File "/home/dgfsmg/virtualenv/repositories/dgfs_back/3.10/lib/python3.10/site-packages/django/utils/functional.py", line 57, in __get__
    res = instance.__dict__[self.name] = self.func(instance)
  File "/home/dgfsmg/virtualenv/repositories/dgfs_back/3.10/lib/python3.10/site-packages/django/urls/resolvers.py", line 715, in url_patterns
    patterns = getattr(self.urlconf_module, "urlpatterns", self.urlconf_module)
  File "/home/dgfsmg/virtualenv/repositories/dgfs_back/3.10/lib/python3.10/site-packages/django/utils/functional.py", line 57, in __get__
    res = instance.__dict__[self.name] = self.func(instance)
  File "/home/dgfsmg/virtualenv/repositories/dgfs_back/3.10/lib/python3.10/site-packages/django/urls/resolvers.py", line 708, in urlconf_module
    return import_module(self.urlconf_name)
  File "/opt/alt/python310/lib64/python3.10/importlib/__init__.py", line 126, in import_module
    return _bootstrap._gcd_import(name[level:], package, level)
  File "<frozen importlib._bootstrap>", line 1050, in _gcd_import
  File "<frozen importlib._bootstrap>", line 1027, in _find_and_load
  File "<frozen importlib._bootstrap>", line 1006, in _find_and_load_unlocked
  File "<frozen importlib._bootstrap>", line 688, in _load_unlocked
  File "<frozen importlib._bootstrap_external>", line 879, in exec_module
  File "<frozen importlib._bootstrap_external>", line 1017, in get_code
  File "<frozen importlib._bootstrap_external>", line 947, in source_to_code
  File "<frozen importlib._bootstrap>", line 241, in _call_with_frames_removed
  File "/home/dgfsmg/repositories/dgfs_back/MainRoot/urls.py", line 29
    urlpatterns += static(settings.MEDIA_URL, document_root=settings.MEDIA_ROOT , staticfiles_urlpatterns())
                                                                                                           ^
SyntaxError: positional argument follows keyword argument
Not Found: /b/
Not Found: /b/api
Not Found: /b/api/
Not Found: /b/
Not Found: /b/
Not Found: /b/
Not Found: /b/
Exception ignored in: <_io.TextIOWrapper name='<stdout>' mode='w' encoding='utf-8'>
BrokenPipeError: [Errno 32] Broken pipe
Not Found: /b/
Not Found: /b/
Not Found: /b/
Not Found: /b/api
Not Found: /b/
Not Found: /b/
Not Found: /b/
Not Found: /b/static/admin/css/base.css
Not Found: /b/static/admin/css/responsive.css
Not Found: /b/static/admin/css/dark_mode.css
Not Found: /b/static/admin/css/login.css
Not Found: /b/static/admin/js/theme.js
Not Found: /b/static/admin/css/nav_sidebar.css
Not Found: /b/static/admin/js/nav_sidebar.js
Not Found: /b/static/admin/css/base.css
Not Found: /b/static/admin/css/base.css
Not Found: /b/
Not Found: /b/static/admin/css/base.css
Not Found: /b/static/admin/js/nav_sidebar.js
Not Found: /b/static/admin/css/responsive.css
Not Found: /b/static/admin/js/theme.js
Not Found: /b/static/admin/css/nav_sidebar.css
Not Found: /b/static/admin/css/dark_mode.css
Not Found: /b/static/admin/css/login.css
Not Found: /b/static/admin/css/base.css
Not Found: /b/static/admin/css/nav_sidebar.css
Not Found: /b/static/admin/js/nav_sidebar.js
Not Found: /b/static/admin/css/login.css
Not Found: /b/static/admin/css/responsive.css
Not Found: /b/static/admin/css/dark_mode.css
Not Found: /b/static/admin/js/theme.js
Not Found: /b/static/admin/css/base.css
Not Found: /b/static/admin/css/nav_sidebar.css
Not Found: /b/static/admin/js/theme.js
Not Found: /b/static/admin/css/nav_sidebar.css
Not Found: /b/static/admin/js/nav_sidebar.js
Not Found: /b/static/admin/css/login.css
Not Found: /b/static/admin/css/dark_mode.css
Not Found: /b/static/admin/css/responsive.css
Not Found: /b/static/admin/css/base.css
Not Found: /b/static/admin/js/theme.js
Not Found: /b/static/admin/css/nav_sidebar.css
Not Found: /b/static/admin/css/dark_mode.css
Not Found: /b/static/admin/css/login.css
Not Found: /b/static/admin/css/base.css
Not Found: /b/static/admin/js/theme.js
Not Found: /b/static/admin/css/nav_sidebar.css
Not Found: /b/static/admin/css/responsive.css
Not Found: /b/static/admin/js/nav_sidebar.js
Not Found: /b/
Not Found: /b/static/admin/css/base.css
Not Found: /b/static/admin/js/nav_sidebar.js
Not Found: /b/static/admin/css/login.css
Not Found: /b/static/admin/css/responsive.css
Not Found: /b/static/admin/css/nav_sidebar.css
Not Found: /b/static/admin/css/dark_mode.css
Not Found: /b/static/admin/js/theme.js
Not Found: /b/static/admin/css/nav_sidebar.css
Not Found: /b/static/admin/css/login.css
Not Found: /b/static/admin/css/dark_mode.css
Not Found: /b/static/admin/css/responsive.css
Not Found: /b/static/admin/css/base.css
Not Found: /b/static/admin/js/nav_sidebar.js
Not Found: /b/static/admin/js/theme.js
Not Found: /b/static/admin/css/nav_sidebar.css
Not Found: /b/static/admin/css/nav_sidebar.css
Not Found: /
Not Found: /
Not Found: /b/
Not Found: /b/static/admin/css/base.css
Not Found: /b/static/admin/js/nav_sidebar.js
Not Found: /b/static/admin/css/dark_mode.css
Not Found: /b/static/admin/css/login.css
Not Found: /b/static/admin/css/responsive.css
Not Found: /b/static/admin/css/nav_sidebar.css
Not Found: /b/static/admin/js/theme.js
Not Found: /b/static/admin/css/login.css
Not Found: /b/static/admin/css/responsive.css
Not Found: /b/static/admin/css/base.css
Not Found: /b/static/admin/js/nav_sidebar.js
Not Found: /b/static/admin/js/theme.js
Not Found: /b/static/admin/css/nav_sidebar.css
Not Found: /b/static/admin/css/dark_mode.css
Not Found: /b/static/admin/css/login.css
Not Found: /b/
Not Found: /b/static/admin/css/base.css
Not Found: /b/static/admin/js/nav_sidebar.js
Not Found: /b/static/admin/css/dark_mode.css
Not Found: /b/static/admin/css/nav_sidebar.css
Not Found: /b/static/admin/css/login.css
Not Found: /b/static/admin/css/responsive.css
Not Found: /b/static/admin/js/theme.js
Not Found: /b/static/admin/css/login.css
Not Found: /b/static/admin/css/base.css
Not Found: /b/static/admin/css/responsive.css
Not Found: /b/static/admin/js/theme.js
Not Found: /b/static/admin/js/nav_sidebar.js
Not Found: /b/static/admin/css/nav_sidebar.css
Not Found: /b/static/admin/css/dark_mode.css
Not Found: /b/static/admin/css/base.css
Not Found: /b/static/admin/js/theme.js
Not Found: /b/static/admin/css/base.css
Not Found: /b/static/admin/css/dark_mode.css
Not Found: /b/static/admin/css/responsive.css
Not Found: /b/static/admin/js/nav_sidebar.js
Not Found: /b/static/admin/css/nav_sidebar.css
Not Found: /b/static/admin/css/login.css
Not Found: /b/static/admin/js/theme.js
Not Found: /
Not Found: /
Not Found: /
Invalid HTTP_HOST header: 'content.dgfs.mg'. You may need to add 'content.dgfs.mg' to ALLOWED_HOSTS.
Traceback (most recent call last):
  File "/home/dgfsmg/virtualenv/repositories/dgfs_back/3.10/lib/python3.10/site-packages/django/core/handlers/exception.py", line 55, in inner
    response = get_response(request)
  File "/home/dgfsmg/virtualenv/repositories/dgfs_back/3.10/lib/python3.10/site-packages/django/utils/deprecation.py", line 133, in __call__
    response = self.process_request(request)
  File "/home/dgfsmg/virtualenv/repositories/dgfs_back/3.10/lib/python3.10/site-packages/django/middleware/common.py", line 48, in process_request
    host = request.get_host()
  File "/home/dgfsmg/virtualenv/repositories/dgfs_back/3.10/lib/python3.10/site-packages/django/http/request.py", line 167, in get_host
    raise DisallowedHost(msg)
django.core.exceptions.DisallowedHost: Invalid HTTP_HOST header: 'content.dgfs.mg'. You may need to add 'content.dgfs.mg' to ALLOWED_HOSTS.
Bad Request: /admin
Not Found: /api
[UID:3250][1811925] Reached max children process limit: 6, extra: 2, current: 8, busy: 8, please increase LSAPI_CHILDREN.
[UID:3250][1811925] Reached max children process limit: 6, extra: 2, current: 8, busy: 8, please increase LSAPI_CHILDREN.
[UID:3250][1811925] Reached max children process limit: 6, extra: 2, current: 8, busy: 8, please increase LSAPI_CHILDREN.
[UID:3250][1811925] Reached max children process limit: 6, extra: 2, current: 8, busy: 8, please increase LSAPI_CHILDREN.
[UID:3250][1811925] Reached max children process limit: 6, extra: 2, current: 8, busy: 8, please increase LSAPI_CHILDREN.
[UID:3250][1811925] Reached max children process limit: 6, extra: 2, current: 8, busy: 8, please increase LSAPI_CHILDREN.
[UID:3250][1811925] Reached max children process limit: 6, extra: 2, current: 8, busy: 8, please increase LSAPI_CHILDREN.
[UID:3250][1811925] Reached max children process limit: 6, extra: 2, current: 8, busy: 8, please increase LSAPI_CHILDREN.
[UID:3250][1811925] Reached max children process limit: 6, extra: 2, current: 8, busy: 8, please increase LSAPI_CHILDREN.
[UID:3250][1811925] Reached max children process limit: 6, extra: 2, current: 8, busy: 8, please increase LSAPI_CHILDREN.
[UID:3250][1811925] Reached max children process limit: 6, extra: 2, current: 8, busy: 8, please increase LSAPI_CHILDREN.
[UID:3250][1811925] Reached max children process limit: 6, extra: 2, current: 8, busy: 8, please increase LSAPI_CHILDREN.
[UID:3250][1811925] Reached max children process limit: 6, extra: 2, current: 8, busy: 8, please increase LSAPI_CHILDREN.
[UID:3250][1811925] Reached max children process limit: 6, extra: 2, current: 8, busy: 8, please increase LSAPI_CHILDREN.
[UID:3250][1811925] Reached max children process limit: 6, extra: 2, current: 8, busy: 8, please increase LSAPI_CHILDREN.
[UID:3250][1811925] Reached max children process limit: 6, extra: 2, current: 8, busy: 8, please increase LSAPI_CHILDREN.
[UID:3250][1811925] Reached max children process limit: 6, extra: 2, current: 8, busy: 8, please increase LSAPI_CHILDREN.
Not Found: /
Not Found: /
Not Found: /
Not Found: /
Not Found: /
Not Found: /
Not Found: /
Not Found: /
[UID:3250][1811925] Reached max children process limit: 6, extra: 2, current: 8, busy: 8, please increase LSAPI_CHILDREN.
[UID:3250][1811925] Reached max children process limit: 6, extra: 2, current: 8, busy: 8, please increase LSAPI_CHILDREN.
[UID:3250][1811925] Reached max children process limit: 6, extra: 2, current: 8, busy: 8, please increase LSAPI_CHILDREN.
[UID:3250][1811925] Reached max children process limit: 6, extra: 2, current: 8, busy: 8, please increase LSAPI_CHILDREN.
[UID:3250][1811925] Reached max children process limit: 6, extra: 2, current: 8, busy: 8, please increase LSAPI_CHILDREN.
[UID:3250][1811925] Reached max children process limit: 6, extra: 2, current: 8, busy: 8, please increase LSAPI_CHILDREN.
[UID:3250][1811925] Reached max children process limit: 6, extra: 2, current: 8, busy: 8, please increase LSAPI_CHILDREN.
[UID:3250][1811925] Reached max children process limit: 6, extra: 2, current: 8, busy: 8, please increase LSAPI_CHILDREN.
[UID:3250][1811925] Reached max children process limit: 6, extra: 2, current: 8, busy: 8, please increase LSAPI_CHILDREN.
[UID:3250][1811925] Reached max children process limit: 6, extra: 2, current: 8, busy: 8, please increase LSAPI_CHILDREN.
[UID:3250][1811925] Reached max children process limit: 6, extra: 2, current: 8, busy: 8, please increase LSAPI_CHILDREN.
[UID:3250][1811925] Reached max children process limit: 6, extra: 2, current: 8, busy: 8, please increase LSAPI_CHILDREN.
[UID:3250][1811925] Reached max children process limit: 6, extra: 2, current: 8, busy: 8, please increase LSAPI_CHILDREN.
[UID:3250][1811925] Reached max children process limit: 6, extra: 2, current: 8, busy: 8, please increase LSAPI_CHILDREN.
[UID:3250][1811925] Reached max children process limit: 6, extra: 2, current: 8, busy: 8, please increase LSAPI_CHILDREN.
[UID:3250][1811925] Reached max children process limit: 6, extra: 2, current: 8, busy: 8, please increase LSAPI_CHILDREN.
[UID:3250][1811925] Reached max children process limit: 6, extra: 2, current: 8, busy: 8, please increase LSAPI_CHILDREN.
[UID:3250][1811925] Reached max children process limit: 6, extra: 2, current: 8, busy: 8, please increase LSAPI_CHILDREN.
[UID:3250][1811925] Reached max children process limit: 6, extra: 2, current: 8, busy: 8, please increase LSAPI_CHILDREN.
[UID:3250][1811925] Reached max children process limit: 6, extra: 2, current: 8, busy: 8, please increase LSAPI_CHILDREN.
[UID:3250][1811925] Reached max children process limit: 6, extra: 2, current: 8, busy: 8, please increase LSAPI_CHILDREN.
[UID:3250][1811925] Reached max children process limit: 6, extra: 2, current: 8, busy: 8, please increase LSAPI_CHILDREN.
[UID:3250][1811925] Reached max children process limit: 6, extra: 2, current: 8, busy: 8, please increase LSAPI_CHILDREN.
[UID:3250][1811925] Reached max children process limit: 6, extra: 2, current: 8, busy: 8, please increase LSAPI_CHILDREN.
[UID:3250][1811925] Reached max children process limit: 6, extra: 2, current: 8, busy: 8, please increase LSAPI_CHILDREN.
[UID:3250][1811925] Reached max children process limit: 6, extra: 2, current: 8, busy: 8, please increase LSAPI_CHILDREN.
Not Found: /
Not Found: /favicon.ico
Not Found: /
Not Found: /
Not Found: /aGTiHOmu
Not Found: /
Not Found: /
Not Found: /sIagYyZHuwy
Not Found: /favicon.ico
Invalid HTTP_HOST header: 'www.content.dgfs.mg'. You may need to add 'www.content.dgfs.mg' to ALLOWED_HOSTS.
Traceback (most recent call last):
  File "/home/dgfsmg/virtualenv/repositories/dgfs_back/3.10/lib/python3.10/site-packages/django/core/handlers/exception.py", line 55, in inner
    response = get_response(request)
  File "/home/dgfsmg/virtualenv/repositories/dgfs_back/3.10/lib/python3.10/site-packages/django/utils/deprecation.py", line 133, in __call__
    response = self.process_request(request)
  File "/home/dgfsmg/virtualenv/repositories/dgfs_back/3.10/lib/python3.10/site-packages/django/middleware/common.py", line 48, in process_request
    host = request.get_host()
  File "/home/dgfsmg/virtualenv/repositories/dgfs_back/3.10/lib/python3.10/site-packages/django/http/request.py", line 167, in get_host
    raise DisallowedHost(msg)
django.core.exceptions.DisallowedHost: Invalid HTTP_HOST header: 'www.content.dgfs.mg'. You may need to add 'www.content.dgfs.mg' to ALLOWED_HOSTS.
Bad Request: /
Invalid HTTP_HOST header: 'www.content.dgfs.mg'. You may need to add 'www.content.dgfs.mg' to ALLOWED_HOSTS.
Traceback (most recent call last):
  File "/home/dgfsmg/virtualenv/repositories/dgfs_back/3.10/lib/python3.10/site-packages/django/core/handlers/exception.py", line 55, in inner
    response = get_response(request)
  File "/home/dgfsmg/virtualenv/repositories/dgfs_back/3.10/lib/python3.10/site-packages/django/utils/deprecation.py", line 133, in __call__
    response = self.process_request(request)
  File "/home/dgfsmg/virtualenv/repositories/dgfs_back/3.10/lib/python3.10/site-packages/django/middleware/common.py", line 48, in process_request
    host = request.get_host()
  File "/home/dgfsmg/virtualenv/repositories/dgfs_back/3.10/lib/python3.10/site-packages/django/http/request.py", line 167, in get_host
    raise DisallowedHost(msg)
django.core.exceptions.DisallowedHost: Invalid HTTP_HOST header: 'www.content.dgfs.mg'. You may need to add 'www.content.dgfs.mg' to ALLOWED_HOSTS.
Bad Request: /
Not Found: /
Not Found: /
Not Found: /
Not Found: /
Invalid HTTP_HOST header: 'www.content.dgfs.mg'. You may need to add 'www.content.dgfs.mg' to ALLOWED_HOSTS.
Traceback (most recent call last):
  File "/home/dgfsmg/virtualenv/repositories/dgfs_back/3.10/lib/python3.10/site-packages/django/core/handlers/exception.py", line 55, in inner
    response = get_response(request)
  File "/home/dgfsmg/virtualenv/repositories/dgfs_back/3.10/lib/python3.10/site-packages/django/utils/deprecation.py", line 133, in __call__
    response = self.process_request(request)
  File "/home/dgfsmg/virtualenv/repositories/dgfs_back/3.10/lib/python3.10/site-packages/django/middleware/common.py", line 48, in process_request
    host = request.get_host()
  File "/home/dgfsmg/virtualenv/repositories/dgfs_back/3.10/lib/python3.10/site-packages/django/http/request.py", line 167, in get_host
    raise DisallowedHost(msg)
django.core.exceptions.DisallowedHost: Invalid HTTP_HOST header: 'www.content.dgfs.mg'. You may need to add 'www.content.dgfs.mg' to ALLOWED_HOSTS.
Bad Request: /
Not Found: /
Not Found: /api
[UID:3250][4093581] Child process with pid: 4115720 was killed by signal: 15, core dumped: no
Not Found: /api/posts
Invalid HTTP_HOST header: 'www.content.dgfs.mg'. You may need to add 'www.content.dgfs.mg' to ALLOWED_HOSTS.
Traceback (most recent call last):
  File "/home/dgfsmg/virtualenv/repositories/dgfs_back/3.10/lib/python3.10/site-packages/django/core/handlers/exception.py", line 55, in inner
    response = get_response(request)
  File "/home/dgfsmg/virtualenv/repositories/dgfs_back/3.10/lib/python3.10/site-packages/django/utils/deprecation.py", line 133, in __call__
    response = self.process_request(request)
  File "/home/dgfsmg/virtualenv/repositories/dgfs_back/3.10/lib/python3.10/site-packages/django/middleware/common.py", line 48, in process_request
    host = request.get_host()
  File "/home/dgfsmg/virtualenv/repositories/dgfs_back/3.10/lib/python3.10/site-packages/django/http/request.py", line 167, in get_host
    raise DisallowedHost(msg)
django.core.exceptions.DisallowedHost: Invalid HTTP_HOST header: 'www.content.dgfs.mg'. You may need to add 'www.content.dgfs.mg' to ALLOWED_HOSTS.
[UID:3250][277475] Child process with pid: 278840 was killed by signal: 15, core dumped: no
Invalid HTTP_HOST header: 'www.content.dgfs.mg'. You may need to add 'www.content.dgfs.mg' to ALLOWED_HOSTS.
Traceback (most recent call last):
  File "/home/dgfsmg/virtualenv/repositories/dgfs_back/3.10/lib/python3.10/site-packages/django/core/handlers/exception.py", line 55, in inner
    response = get_response(request)
  File "/home/dgfsmg/virtualenv/repositories/dgfs_back/3.10/lib/python3.10/site-packages/django/utils/deprecation.py", line 133, in __call__
    response = self.process_request(request)
  File "/home/dgfsmg/virtualenv/repositories/dgfs_back/3.10/lib/python3.10/site-packages/django/middleware/common.py", line 48, in process_request
    host = request.get_host()
  File "/home/dgfsmg/virtualenv/repositories/dgfs_back/3.10/lib/python3.10/site-packages/django/http/request.py", line 167, in get_host
    raise DisallowedHost(msg)
django.core.exceptions.DisallowedHost: Invalid HTTP_HOST header: 'www.content.dgfs.mg'. You may need to add 'www.content.dgfs.mg' to ALLOWED_HOSTS.
Bad Request: /
Invalid HTTP_HOST header: 'www.content.dgfs.mg'. You may need to add 'www.content.dgfs.mg' to ALLOWED_HOSTS.
Traceback (most recent call last):
  File "/home/dgfsmg/virtualenv/repositories/dgfs_back/3.10/lib/python3.10/site-packages/django/core/handlers/exception.py", line 55, in inner
    response = get_response(request)
  File "/home/dgfsmg/virtualenv/repositories/dgfs_back/3.10/lib/python3.10/site-packages/django/utils/deprecation.py", line 133, in __call__
    response = self.process_request(request)
  File "/home/dgfsmg/virtualenv/repositories/dgfs_back/3.10/lib/python3.10/site-packages/django/middleware/common.py", line 48, in process_request
    host = request.get_host()
  File "/home/dgfsmg/virtualenv/repositories/dgfs_back/3.10/lib/python3.10/site-packages/django/http/request.py", line 167, in get_host
    raise DisallowedHost(msg)
django.core.exceptions.DisallowedHost: Invalid HTTP_HOST header: 'www.content.dgfs.mg'. You may need to add 'www.content.dgfs.mg' to ALLOWED_HOSTS.
Bad Request: /favicon.ico
Not Found: /
Not Found: /favicon.ico
Not Found: /
[UID:3250][444837] Child process with pid: 445836 was killed by signal: 15, core dumped: no
Not Found: /
Not Found: /
Not Found: /
Invalid HTTP_HOST header: 'www.content.dgfs.mg'. You may need to add 'www.content.dgfs.mg' to ALLOWED_HOSTS.
Traceback (most recent call last):
  File "/home/dgfsmg/virtualenv/repositories/dgfs_back/3.10/lib/python3.10/site-packages/django/core/handlers/exception.py", line 55, in inner
    response = get_response(request)
  File "/home/dgfsmg/virtualenv/repositories/dgfs_back/3.10/lib/python3.10/site-packages/django/utils/deprecation.py", line 133, in __call__
    response = self.process_request(request)
  File "/home/dgfsmg/virtualenv/repositories/dgfs_back/3.10/lib/python3.10/site-packages/django/middleware/common.py", line 48, in process_request
    host = request.get_host()
  File "/home/dgfsmg/virtualenv/repositories/dgfs_back/3.10/lib/python3.10/site-packages/django/http/request.py", line 167, in get_host
    raise DisallowedHost(msg)
django.core.exceptions.DisallowedHost: Invalid HTTP_HOST header: 'www.content.dgfs.mg'. You may need to add 'www.content.dgfs.mg' to ALLOWED_HOSTS.
Bad Request: /
[UID:3250][1793264] Child process with pid: 1839717 was killed by signal: 15, core dumped: no
[UID:3250][1793264] Child process with pid: 1839904 was killed by signal: 15, core dumped: no
[UID:3250][3281078] Child process with pid: 3281789 was killed by signal: 9, core dumped: no
Invalid HTTP_HOST header: 'www.content.dgfs.mg'. You may need to add 'www.content.dgfs.mg' to ALLOWED_HOSTS.
Traceback (most recent call last):
  File "/home/dgfsmg/virtualenv/repositories/dgfs_back/3.10/lib/python3.10/site-packages/django/core/handlers/exception.py", line 55, in inner
    response = get_response(request)
  File "/home/dgfsmg/virtualenv/repositories/dgfs_back/3.10/lib/python3.10/site-packages/django/utils/deprecation.py", line 133, in __call__
    response = self.process_request(request)
  File "/home/dgfsmg/virtualenv/repositories/dgfs_back/3.10/lib/python3.10/site-packages/django/middleware/common.py", line 48, in process_request
    host = request.get_host()
  File "/home/dgfsmg/virtualenv/repositories/dgfs_back/3.10/lib/python3.10/site-packages/django/http/request.py", line 167, in get_host
    raise DisallowedHost(msg)
django.core.exceptions.DisallowedHost: Invalid HTTP_HOST header: 'www.content.dgfs.mg'. You may need to add 'www.content.dgfs.mg' to ALLOWED_HOSTS.
Bad Request: /
Invalid HTTP_HOST header: 'www.content.dgfs.mg'. You may need to add 'www.content.dgfs.mg' to ALLOWED_HOSTS.
Traceback (most recent call last):
  File "/home/dgfsmg/virtualenv/repositories/dgfs_back/3.10/lib/python3.10/site-packages/django/core/handlers/exception.py", line 55, in inner
    response = get_response(request)
  File "/home/dgfsmg/virtualenv/repositories/dgfs_back/3.10/lib/python3.10/site-packages/django/utils/deprecation.py", line 133, in __call__
    response = self.process_request(request)
  File "/home/dgfsmg/virtualenv/repositories/dgfs_back/3.10/lib/python3.10/site-packages/django/middleware/common.py", line 48, in process_request
    host = request.get_host()
  File "/home/dgfsmg/virtualenv/repositories/dgfs_back/3.10/lib/python3.10/site-packages/django/http/request.py", line 167, in get_host
    raise DisallowedHost(msg)
django.core.exceptions.DisallowedHost: Invalid HTTP_HOST header: 'www.content.dgfs.mg'. You may need to add 'www.content.dgfs.mg' to ALLOWED_HOSTS.
Invalid HTTP_HOST header: 'www.content.dgfs.mg'. You may need to add 'www.content.dgfs.mg' to ALLOWED_HOSTS.
Traceback (most recent call last):
  File "/home/dgfsmg/virtualenv/repositories/dgfs_back/3.10/lib/python3.10/site-packages/django/core/handlers/exception.py", line 55, in inner
    response = get_response(request)
  File "/home/dgfsmg/virtualenv/repositories/dgfs_back/3.10/lib/python3.10/site-packages/django/utils/deprecation.py", line 133, in __call__
    response = self.process_request(request)
  File "/home/dgfsmg/virtualenv/repositories/dgfs_back/3.10/lib/python3.10/site-packages/django/middleware/common.py", line 48, in process_request
    host = request.get_host()
  File "/home/dgfsmg/virtualenv/repositories/dgfs_back/3.10/lib/python3.10/site-packages/django/http/request.py", line 167, in get_host
    raise DisallowedHost(msg)
django.core.exceptions.DisallowedHost: Invalid HTTP_HOST header: 'www.content.dgfs.mg'. You may need to add 'www.content.dgfs.mg' to ALLOWED_HOSTS.
Not Found: /
Bad Request: /
Bad Request: /
Not Found: /
Invalid HTTP_HOST header: 'www.content.dgfs.mg'. You may need to add 'www.content.dgfs.mg' to ALLOWED_HOSTS.
Traceback (most recent call last):
  File "/home/dgfsmg/virtualenv/repositories/dgfs_back/3.10/lib/python3.10/site-packages/django/core/handlers/exception.py", line 55, in inner
    response = get_response(request)
  File "/home/dgfsmg/virtualenv/repositories/dgfs_back/3.10/lib/python3.10/site-packages/django/utils/deprecation.py", line 133, in __call__
    response = self.process_request(request)
  File "/home/dgfsmg/virtualenv/repositories/dgfs_back/3.10/lib/python3.10/site-packages/django/middleware/common.py", line 48, in process_request
    host = request.get_host()
  File "/home/dgfsmg/virtualenv/repositories/dgfs_back/3.10/lib/python3.10/site-packages/django/http/request.py", line 167, in get_host
    raise DisallowedHost(msg)
django.core.exceptions.DisallowedHost: Invalid HTTP_HOST header: 'www.content.dgfs.mg'. You may need to add 'www.content.dgfs.mg' to ALLOWED_HOSTS.
Invalid HTTP_HOST header: 'www.content.dgfs.mg'. You may need to add 'www.content.dgfs.mg' to ALLOWED_HOSTS.
Traceback (most recent call last):
  File "/home/dgfsmg/virtualenv/repositories/dgfs_back/3.10/lib/python3.10/site-packages/django/core/handlers/exception.py", line 55, in inner
    response = get_response(request)
  File "/home/dgfsmg/virtualenv/repositories/dgfs_back/3.10/lib/python3.10/site-packages/django/utils/deprecation.py", line 133, in __call__
    response = self.process_request(request)
  File "/home/dgfsmg/virtualenv/repositories/dgfs_back/3.10/lib/python3.10/site-packages/django/middleware/common.py", line 48, in process_request
    host = request.get_host()
  File "/home/dgfsmg/virtualenv/repositories/dgfs_back/3.10/lib/python3.10/site-packages/django/http/request.py", line 167, in get_host
    raise DisallowedHost(msg)
django.core.exceptions.DisallowedHost: Invalid HTTP_HOST header: 'www.content.dgfs.mg'. You may need to add 'www.content.dgfs.mg' to ALLOWED_HOSTS.
Bad Request: /
Bad Request: /
Not Found: /
Not Found: /
Not Found: /
Not Found: /
Not Found: /favicon.ico
Invalid HTTP_HOST header: 'www.content.dgfs.mg'. You may need to add 'www.content.dgfs.mg' to ALLOWED_HOSTS.
Traceback (most recent call last):
  File "/home/dgfsmg/virtualenv/repositories/dgfs_back/3.10/lib/python3.10/site-packages/django/core/handlers/exception.py", line 55, in inner
    response = get_response(request)
  File "/home/dgfsmg/virtualenv/repositories/dgfs_back/3.10/lib/python3.10/site-packages/django/utils/deprecation.py", line 133, in __call__
    response = self.process_request(request)
  File "/home/dgfsmg/virtualenv/repositories/dgfs_back/3.10/lib/python3.10/site-packages/django/middleware/common.py", line 48, in process_request
    host = request.get_host()
  File "/home/dgfsmg/virtualenv/repositories/dgfs_back/3.10/lib/python3.10/site-packages/django/http/request.py", line 167, in get_host
    raise DisallowedHost(msg)
django.core.exceptions.DisallowedHost: Invalid HTTP_HOST header: 'www.content.dgfs.mg'. You may need to add 'www.content.dgfs.mg' to ALLOWED_HOSTS.
Bad Request: /
Not Found: /
Invalid HTTP_HOST header: 'www.content.dgfs.mg'. You may need to add 'www.content.dgfs.mg' to ALLOWED_HOSTS.
Traceback (most recent call last):
  File "/home/dgfsmg/virtualenv/repositories/dgfs_back/3.10/lib/python3.10/site-packages/django/core/handlers/exception.py", line 55, in inner
    response = get_response(request)
  File "/home/dgfsmg/virtualenv/repositories/dgfs_back/3.10/lib/python3.10/site-packages/django/utils/deprecation.py", line 133, in __call__
    response = self.process_request(request)
  File "/home/dgfsmg/virtualenv/repositories/dgfs_back/3.10/lib/python3.10/site-packages/django/middleware/common.py", line 48, in process_request
    host = request.get_host()
  File "/home/dgfsmg/virtualenv/repositories/dgfs_back/3.10/lib/python3.10/site-packages/django/http/request.py", line 167, in get_host
    raise DisallowedHost(msg)
django.core.exceptions.DisallowedHost: Invalid HTTP_HOST header: 'www.content.dgfs.mg'. You may need to add 'www.content.dgfs.mg' to ALLOWED_HOSTS.
Bad Request: /
Invalid HTTP_HOST header: 'www.content.dgfs.mg'. You may need to add 'www.content.dgfs.mg' to ALLOWED_HOSTS.
Traceback (most recent call last):
  File "/home/dgfsmg/virtualenv/repositories/dgfs_back/3.10/lib/python3.10/site-packages/django/core/handlers/exception.py", line 55, in inner
    response = get_response(request)
  File "/home/dgfsmg/virtualenv/repositories/dgfs_back/3.10/lib/python3.10/site-packages/django/utils/deprecation.py", line 133, in __call__
    response = self.process_request(request)
  File "/home/dgfsmg/virtualenv/repositories/dgfs_back/3.10/lib/python3.10/site-packages/django/middleware/common.py", line 48, in process_request
    host = request.get_host()
  File "/home/dgfsmg/virtualenv/repositories/dgfs_back/3.10/lib/python3.10/site-packages/django/http/request.py", line 167, in get_host
    raise DisallowedHost(msg)
django.core.exceptions.DisallowedHost: Invalid HTTP_HOST header: 'www.content.dgfs.mg'. You may need to add 'www.content.dgfs.mg' to ALLOWED_HOSTS.
Bad Request: /
Not Found: /
Invalid HTTP_HOST header: 'www.content.dgfs.mg'. You may need to add 'www.content.dgfs.mg' to ALLOWED_HOSTS.
Traceback (most recent call last):
  File "/home/dgfsmg/virtualenv/repositories/dgfs_back/3.10/lib/python3.10/site-packages/django/core/handlers/exception.py", line 55, in inner
    response = get_response(request)
  File "/home/dgfsmg/virtualenv/repositories/dgfs_back/3.10/lib/python3.10/site-packages/django/utils/deprecation.py", line 133, in __call__
    response = self.process_request(request)
  File "/home/dgfsmg/virtualenv/repositories/dgfs_back/3.10/lib/python3.10/site-packages/django/middleware/common.py", line 48, in process_request
    host = request.get_host()
  File "/home/dgfsmg/virtualenv/repositories/dgfs_back/3.10/lib/python3.10/site-packages/django/http/request.py", line 167, in get_host
    raise DisallowedHost(msg)
django.core.exceptions.DisallowedHost: Invalid HTTP_HOST header: 'www.content.dgfs.mg'. You may need to add 'www.content.dgfs.mg' to ALLOWED_HOSTS.
Bad Request: /
Invalid HTTP_HOST header: 'www.content.dgfs.mg'. You may need to add 'www.content.dgfs.mg' to ALLOWED_HOSTS.
Traceback (most recent call last):
  File "/home/dgfsmg/virtualenv/repositories/dgfs_back/3.10/lib/python3.10/site-packages/django/core/handlers/exception.py", line 55, in inner
    response = get_response(request)
  File "/home/dgfsmg/virtualenv/repositories/dgfs_back/3.10/lib/python3.10/site-packages/django/utils/deprecation.py", line 133, in __call__
    response = self.process_request(request)
  File "/home/dgfsmg/virtualenv/repositories/dgfs_back/3.10/lib/python3.10/site-packages/django/middleware/common.py", line 48, in process_request
    host = request.get_host()
  File "/home/dgfsmg/virtualenv/repositories/dgfs_back/3.10/lib/python3.10/site-packages/django/http/request.py", line 167, in get_host
    raise DisallowedHost(msg)
django.core.exceptions.DisallowedHost: Invalid HTTP_HOST header: 'www.content.dgfs.mg'. You may need to add 'www.content.dgfs.mg' to ALLOWED_HOSTS.
Bad Request: /
Invalid HTTP_HOST header: 'www.content.dgfs.mg'. You may need to add 'www.content.dgfs.mg' to ALLOWED_HOSTS.
Traceback (most recent call last):
  File "/home/dgfsmg/virtualenv/repositories/dgfs_back/3.10/lib/python3.10/site-packages/django/core/handlers/exception.py", line 55, in inner
    response = get_response(request)
  File "/home/dgfsmg/virtualenv/repositories/dgfs_back/3.10/lib/python3.10/site-packages/django/utils/deprecation.py", line 133, in __call__
    response = self.process_request(request)
  File "/home/dgfsmg/virtualenv/repositories/dgfs_back/3.10/lib/python3.10/site-packages/django/middleware/common.py", line 48, in process_request
    host = request.get_host()
  File "/home/dgfsmg/virtualenv/repositories/dgfs_back/3.10/lib/python3.10/site-packages/django/http/request.py", line 167, in get_host
    raise DisallowedHost(msg)
django.core.exceptions.DisallowedHost: Invalid HTTP_HOST header: 'www.content.dgfs.mg'. You may need to add 'www.content.dgfs.mg' to ALLOWED_HOSTS.
Bad Request: /favicon.ico
Not Found: /
Not Found: /
[UID:3250][888630] Child process with pid: 889874 was killed by signal: 9, core dumped: no
Not Found: /
[UID:3250][3099577] Child process with pid: 3100802 was killed by signal: 15, core dumped: no
Not Found: /
Not Found: /
Not Found: /
Not Found: /
Invalid HTTP_HOST header: 'www.content.dgfs.mg'. You may need to add 'www.content.dgfs.mg' to ALLOWED_HOSTS.
Traceback (most recent call last):
  File "/home/dgfsmg/virtualenv/repositories/dgfs_back/3.10/lib/python3.10/site-packages/django/core/handlers/exception.py", line 55, in inner
    response = get_response(request)
  File "/home/dgfsmg/virtualenv/repositories/dgfs_back/3.10/lib/python3.10/site-packages/django/utils/deprecation.py", line 133, in __call__
    response = self.process_request(request)
  File "/home/dgfsmg/virtualenv/repositories/dgfs_back/3.10/lib/python3.10/site-packages/django/middleware/common.py", line 48, in process_request
    host = request.get_host()
  File "/home/dgfsmg/virtualenv/repositories/dgfs_back/3.10/lib/python3.10/site-packages/django/http/request.py", line 167, in get_host
    raise DisallowedHost(msg)
django.core.exceptions.DisallowedHost: Invalid HTTP_HOST header: 'www.content.dgfs.mg'. You may need to add 'www.content.dgfs.mg' to ALLOWED_HOSTS.
Bad Request: /
Invalid HTTP_HOST header: 'www.content.dgfs.mg'. You may need to add 'www.content.dgfs.mg' to ALLOWED_HOSTS.
Traceback (most recent call last):
  File "/home/dgfsmg/virtualenv/repositories/dgfs_back/3.10/lib/python3.10/site-packages/django/core/handlers/exception.py", line 55, in inner
    response = get_response(request)
  File "/home/dgfsmg/virtualenv/repositories/dgfs_back/3.10/lib/python3.10/site-packages/django/utils/deprecation.py", line 133, in __call__
    response = self.process_request(request)
  File "/home/dgfsmg/virtualenv/repositories/dgfs_back/3.10/lib/python3.10/site-packages/django/middleware/common.py", line 48, in process_request
    host = request.get_host()
  File "/home/dgfsmg/virtualenv/repositories/dgfs_back/3.10/lib/python3.10/site-packages/django/http/request.py", line 167, in get_host
    raise DisallowedHost(msg)
django.core.exceptions.DisallowedHost: Invalid HTTP_HOST header: 'www.content.dgfs.mg'. You may need to add 'www.content.dgfs.mg' to ALLOWED_HOSTS.
Bad Request: /
Invalid HTTP_HOST header: 'content.dgfs.mg'. You may need to add 'content.dgfs.mg' to ALLOWED_HOSTS.
Traceback (most recent call last):
  File "/home/dgfsmg/virtualenv/repositories/dgfs_back/3.10/lib/python3.10/site-packages/django/core/handlers/exception.py", line 55, in inner
    response = get_response(request)
  File "/home/dgfsmg/virtualenv/repositories/dgfs_back/3.10/lib/python3.10/site-packages/django/utils/deprecation.py", line 133, in __call__
    response = self.process_request(request)
  File "/home/dgfsmg/virtualenv/repositories/dgfs_back/3.10/lib/python3.10/site-packages/django/middleware/common.py", line 48, in process_request
    host = request.get_host()
  File "/home/dgfsmg/virtualenv/repositories/dgfs_back/3.10/lib/python3.10/site-packages/django/http/request.py", line 167, in get_host
    raise DisallowedHost(msg)
django.core.exceptions.DisallowedHost: Invalid HTTP_HOST header: 'content.dgfs.mg'. You may need to add 'content.dgfs.mg' to ALLOWED_HOSTS.
Bad Request: /api/post
Invalid HTTP_HOST header: 'content.dgfs.mg'. You may need to add 'content.dgfs.mg' to ALLOWED_HOSTS.
Traceback (most recent call last):
  File "/home/dgfsmg/virtualenv/repositories/dgfs_back/3.10/lib/python3.10/site-packages/django/core/handlers/exception.py", line 55, in inner
    response = get_response(request)
  File "/home/dgfsmg/virtualenv/repositories/dgfs_back/3.10/lib/python3.10/site-packages/django/utils/deprecation.py", line 133, in __call__
    response = self.process_request(request)
  File "/home/dgfsmg/virtualenv/repositories/dgfs_back/3.10/lib/python3.10/site-packages/django/middleware/common.py", line 48, in process_request
    host = request.get_host()
  File "/home/dgfsmg/virtualenv/repositories/dgfs_back/3.10/lib/python3.10/site-packages/django/http/request.py", line 167, in get_host
    raise DisallowedHost(msg)
django.core.exceptions.DisallowedHost: Invalid HTTP_HOST header: 'content.dgfs.mg'. You may need to add 'content.dgfs.mg' to ALLOWED_HOSTS.
Bad Request: /api/post
Not Found: /media/post_44d50bf2-1306-4218-9fd7-3ddea25100eb/article_2_choix1.jpeg
Not Found: /favicon.ico
Not Found: /media/post_5b52dc92-684c-4000-848a-de8195635cca/
Not Found: /media/
Internal Server Error: /api/direction/01a7661e8aef494d92f436a93c3bfa32/
Traceback (most recent call last):
  File "/home/dgfsmg/virtualenv/repositories/dgfs_back/3.10/lib/python3.10/site-packages/rest_framework/fields.py", line 446, in get_attribute
    return get_attribute(instance, self.source_attrs)
  File "/home/dgfsmg/virtualenv/repositories/dgfs_back/3.10/lib/python3.10/site-packages/rest_framework/fields.py", line 96, in get_attribute
    instance = getattr(instance, attr)
AttributeError: type object 'Http404' has no attribute 'name'

During handling of the above exception, another exception occurred:

Traceback (most recent call last):
  File "/home/dgfsmg/virtualenv/repositories/dgfs_back/3.10/lib/python3.10/site-packages/django/core/handlers/exception.py", line 55, in inner
    response = get_response(request)
  File "/home/dgfsmg/virtualenv/repositories/dgfs_back/3.10/lib/python3.10/site-packages/django/core/handlers/base.py", line 197, in _get_response
    response = wrapped_callback(request, *callback_args, **callback_kwargs)
  File "/home/dgfsmg/virtualenv/repositories/dgfs_back/3.10/lib/python3.10/site-packages/django/views/decorators/csrf.py", line 56, in wrapper_view
    return view_func(*args, **kwargs)
  File "/home/dgfsmg/virtualenv/repositories/dgfs_back/3.10/lib/python3.10/site-packages/rest_framework/viewsets.py", line 125, in view
    return self.dispatch(request, *args, **kwargs)
  File "/home/dgfsmg/virtualenv/repositories/dgfs_back/3.10/lib/python3.10/site-packages/rest_framework/views.py", line 509, in dispatch
    response = self.handle_exception(exc)
  File "/home/dgfsmg/virtualenv/repositories/dgfs_back/3.10/lib/python3.10/site-packages/rest_framework/views.py", line 469, in handle_exception
    self.raise_uncaught_exception(exc)
  File "/home/dgfsmg/virtualenv/repositories/dgfs_back/3.10/lib/python3.10/site-packages/rest_framework/views.py", line 480, in raise_uncaught_exception
    raise exc
  File "/home/dgfsmg/virtualenv/repositories/dgfs_back/3.10/lib/python3.10/site-packages/rest_framework/views.py", line 506, in dispatch
    response = handler(request, *args, **kwargs)
  File "/home/dgfsmg/virtualenv/repositories/dgfs_back/3.10/lib/python3.10/site-packages/rest_framework/mixins.py", line 56, in retrieve
    return Response(serializer.data)
  File "/home/dgfsmg/virtualenv/repositories/dgfs_back/3.10/lib/python3.10/site-packages/rest_framework/serializers.py", line 555, in data
    ret = super().data
  File "/home/dgfsmg/virtualenv/repositories/dgfs_back/3.10/lib/python3.10/site-packages/rest_framework/serializers.py", line 253, in data
    self._data = self.to_representation(self.instance)
  File "/home/dgfsmg/virtualenv/repositories/dgfs_back/3.10/lib/python3.10/site-packages/rest_framework/serializers.py", line 509, in to_representation
    attribute = field.get_attribute(instance)
  File "/home/dgfsmg/virtualenv/repositories/dgfs_back/3.10/lib/python3.10/site-packages/rest_framework/fields.py", line 479, in get_attribute
    raise type(exc)(msg)
AttributeError: Got AttributeError when attempting to get a value for field `name` on serializer `DirectionSerializer`.
The serializer field might be named incorrectly and not match any attribute or key on the `type` instance.
Original exception text was: type object 'Http404' has no attribute 'name'.
[UID:3250][286824] Reached max children process limit: 6, extra: 2, current: 8, busy: 7, please increase LSAPI_CHILDREN.
[UID:3250][286824] Reached max children process limit: 6, extra: 2, current: 8, busy: 8, please increase LSAPI_CHILDREN.
[UID:3250][286824] Reached max children process limit: 6, extra: 2, current: 8, busy: 8, please increase LSAPI_CHILDREN.
[UID:3250][286824] Reached max children process limit: 6, extra: 2, current: 8, busy: 8, please increase LSAPI_CHILDREN.
[UID:3250][286824] Reached max children process limit: 6, extra: 2, current: 8, busy: 8, please increase LSAPI_CHILDREN.
[UID:3250][286824] Reached max children process limit: 6, extra: 2, current: 8, busy: 8, please increase LSAPI_CHILDREN.
[UID:3250][286824] Reached max children process limit: 6, extra: 2, current: 8, busy: 8, please increase LSAPI_CHILDREN.
[UID:3250][286824] Reached max children process limit: 6, extra: 2, current: 8, busy: 8, please increase LSAPI_CHILDREN.
[UID:3250][286824] Reached max children process limit: 6, extra: 2, current: 8, busy: 8, please increase LSAPI_CHILDREN.
[UID:3250][286824] Reached max children process limit: 6, extra: 2, current: 8, busy: 8, please increase LSAPI_CHILDREN.
[UID:3250][286824] Reached max children process limit: 6, extra: 2, current: 8, busy: 8, please increase LSAPI_CHILDREN.
[UID:3250][286824] Reached max children process limit: 6, extra: 2, current: 8, busy: 8, please increase LSAPI_CHILDREN.
[UID:3250][286824] Reached max children process limit: 6, extra: 2, current: 8, busy: 8, please increase LSAPI_CHILDREN.
[UID:3250][286824] Reached max children process limit: 6, extra: 2, current: 8, busy: 8, please increase LSAPI_CHILDREN.
[UID:3250][286824] Reached max children process limit: 6, extra: 2, current: 8, busy: 8, please increase LSAPI_CHILDREN.
[UID:3250][286824] Reached max children process limit: 6, extra: 2, current: 8, busy: 8, please increase LSAPI_CHILDREN.
[UID:3250][286824] Reached max children process limit: 6, extra: 2, current: 8, busy: 8, please increase LSAPI_CHILDREN.
[UID:3250][286824] Reached max children process limit: 6, extra: 2, current: 8, busy: 8, please increase LSAPI_CHILDREN.
[UID:3250][286824] Reached max children process limit: 6, extra: 2, current: 8, busy: 8, please increase LSAPI_CHILDREN.
[UID:3250][286824] Reached max children process limit: 6, extra: 2, current: 8, busy: 8, please increase LSAPI_CHILDREN.
[UID:3250][286824] Reached max children process limit: 6, extra: 2, current: 8, busy: 8, please increase LSAPI_CHILDREN.
[UID:3250][286824] Reached max children process limit: 6, extra: 2, current: 8, busy: 8, please increase LSAPI_CHILDREN.
[UID:3250][286824] Reached max children process limit: 6, extra: 2, current: 8, busy: 8, please increase LSAPI_CHILDREN.
[UID:3250][286824] Reached max children process limit: 6, extra: 2, current: 8, busy: 8, please increase LSAPI_CHILDREN.
[UID:3250][286824] Reached max children process limit: 6, extra: 2, current: 8, busy: 8, please increase LSAPI_CHILDREN.
[UID:3250][286824] Reached max children process limit: 6, extra: 2, current: 8, busy: 7, please increase LSAPI_CHILDREN.
[UID:3250][286824] Reached max children process limit: 6, extra: 2, current: 8, busy: 8, please increase LSAPI_CHILDREN.
[UID:3250][286824] Reached max children process limit: 6, extra: 2, current: 8, busy: 8, please increase LSAPI_CHILDREN.
[UID:3250][286824] Reached max children process limit: 6, extra: 2, current: 8, busy: 8, please increase LSAPI_CHILDREN.
[UID:3250][286824] Reached max children process limit: 6, extra: 2, current: 8, busy: 8, please increase LSAPI_CHILDREN.
[UID:3250][286824] Reached max children process limit: 6, extra: 2, current: 8, busy: 8, please increase LSAPI_CHILDREN.
[UID:3250][286824] Reached max children process limit: 6, extra: 2, current: 8, busy: 7, please increase LSAPI_CHILDREN.
[UID:3250][286824] Reached max children process limit: 6, extra: 2, current: 8, busy: 7, please increase LSAPI_CHILDREN.
[UID:3250][286824] Reached max children process limit: 6, extra: 2, current: 8, busy: 7, please increase LSAPI_CHILDREN.
[UID:3250][286824] Reached max children process limit: 6, extra: 2, current: 8, busy: 7, please increase LSAPI_CHILDREN.
[UID:3250][286824] Reached max children process limit: 6, extra: 2, current: 8, busy: 8, please increase LSAPI_CHILDREN.
[UID:3250][286824] Reached max children process limit: 6, extra: 2, current: 8, busy: 8, please increase LSAPI_CHILDREN.
[UID:3250][286824] Reached max children process limit: 6, extra: 2, current: 8, busy: 8, please increase LSAPI_CHILDREN.
[UID:3250][286824] Reached max children process limit: 6, extra: 2, current: 8, busy: 8, please increase LSAPI_CHILDREN.
[UID:3250][286824] Reached max children process limit: 6, extra: 2, current: 8, busy: 8, please increase LSAPI_CHILDREN.
[UID:3250][286824] Reached max children process limit: 6, extra: 2, current: 8, busy: 8, please increase LSAPI_CHILDREN.
[UID:3250][286824] Reached max children process limit: 6, extra: 2, current: 8, busy: 8, please increase LSAPI_CHILDREN.
[UID:3250][286824] Reached max children process limit: 6, extra: 2, current: 8, busy: 8, please increase LSAPI_CHILDREN.
[UID:3250][286824] Reached max children process limit: 6, extra: 2, current: 8, busy: 8, please increase LSAPI_CHILDREN.
[UID:3250][286824] Reached max children process limit: 6, extra: 2, current: 8, busy: 8, please increase LSAPI_CHILDREN.
[UID:3250][286824] Reached max children process limit: 6, extra: 2, current: 8, busy: 8, please increase LSAPI_CHILDREN.
[UID:3250][286824] Reached max children process limit: 6, extra: 2, current: 8, busy: 8, please increase LSAPI_CHILDREN.
[UID:3250][286824] Reached max children process limit: 6, extra: 2, current: 8, busy: 7, please increase LSAPI_CHILDREN.
[UID:3250][286824] Reached max children process limit: 6, extra: 2, current: 8, busy: 8, please increase LSAPI_CHILDREN.
[UID:3250][286824] Reached max children process limit: 6, extra: 2, current: 8, busy: 8, please increase LSAPI_CHILDREN.
[UID:3250][286824] Reached max children process limit: 6, extra: 2, current: 8, busy: 8, please increase LSAPI_CHILDREN.
[UID:3250][286824] Reached max children process limit: 6, extra: 2, current: 8, busy: 7, please increase LSAPI_CHILDREN.
[UID:3250][286824] Reached max children process limit: 6, extra: 2, current: 8, busy: 8, please increase LSAPI_CHILDREN.
[UID:3250][286824] Reached max children process limit: 6, extra: 2, current: 8, busy: 8, please increase LSAPI_CHILDREN.
[UID:3250][286824] Reached max children process limit: 6, extra: 2, current: 8, busy: 8, please increase LSAPI_CHILDREN.
[UID:3250][286824] Reached max children process limit: 6, extra: 2, current: 8, busy: 8, please increase LSAPI_CHILDREN.
[UID:3250][286824] Reached max children process limit: 6, extra: 2, current: 8, busy: 8, please increase LSAPI_CHILDREN.
[UID:3250][286824] Reached max children process limit: 6, extra: 2, current: 8, busy: 8, please increase LSAPI_CHILDREN.
[UID:3250][286824] Reached max children process limit: 6, extra: 2, current: 8, busy: 8, please increase LSAPI_CHILDREN.
[UID:3250][286824] Reached max children process limit: 6, extra: 2, current: 8, busy: 8, please increase LSAPI_CHILDREN.
[UID:3250][286824] Reached max children process limit: 6, extra: 2, current: 8, busy: 8, please increase LSAPI_CHILDREN.
[UID:3250][286824] Reached max children process limit: 6, extra: 2, current: 8, busy: 8, please increase LSAPI_CHILDREN.
[UID:3250][286824] Reached max children process limit: 6, extra: 2, current: 8, busy: 8, please increase LSAPI_CHILDREN.
[UID:3250][286824] Reached max children process limit: 6, extra: 2, current: 8, busy: 8, please increase LSAPI_CHILDREN.
[UID:3250][286824] Reached max children process limit: 6, extra: 2, current: 8, busy: 8, please increase LSAPI_CHILDREN.
[UID:3250][286824] Reached max children process limit: 6, extra: 2, current: 8, busy: 8, please increase LSAPI_CHILDREN.
[UID:3250][286824] Reached max children process limit: 6, extra: 2, current: 8, busy: 8, please increase LSAPI_CHILDREN.
[UID:3250][286824] Reached max children process limit: 6, extra: 2, current: 8, busy: 8, please increase LSAPI_CHILDREN.
[UID:3250][286824] Reached max children process limit: 6, extra: 2, current: 8, busy: 7, please increase LSAPI_CHILDREN.
[UID:3250][286824] Reached max children process limit: 6, extra: 2, current: 8, busy: 8, please increase LSAPI_CHILDREN.
[UID:3250][286824] Reached max children process limit: 6, extra: 2, current: 8, busy: 8, please increase LSAPI_CHILDREN.
[UID:3250][286824] Reached max children process limit: 6, extra: 2, current: 8, busy: 8, please increase LSAPI_CHILDREN.
[UID:3250][286824] Reached max children process limit: 6, extra: 2, current: 8, busy: 7, please increase LSAPI_CHILDREN.
[UID:3250][1862471] [UID:3250][1862471] Child process with pid: 1965535 was killed by signal: 9, core dumped: no
[UID:3250][1862471] Child process with pid: 1965536 was killed by signal: 9, core dumped: no
[UID:3250][1862471] Child process with pid: 1965537 was killed by signal: 9, core dumped: no
[UID:3250][1862471] Child process with pid: 1965538 was killed by signal: 9, core dumped: no
[UID:3250][1862471] Child process with pid: 1965547 was killed by signal: 9, core dumped: no
Reached max children process limit: 6, extra: 2, current: 8, busy: 8, please increase LSAPI_CHILDREN.
[UID:3250][1862471] Child process with pid: 1965637 was killed by signal: 15, core dumped: no
[UID:3250][2223680] Child process with pid: 2226945 was killed by signal: 15, core dumped: no
[UID:3250][2223680] Child process with pid: 2226949 was killed by signal: 15, core dumped: no
[UID:3250][2223680] Child process with pid: 2226959 was killed by signal: 15, core dumped: no
[UID:3250][2223680] Child process with pid: 2226958 was killed by signal: 15, core dumped: no
[UID:3250][3375050] Child process with pid: 3381758 was killed by signal: 9, core dumped: no
[UID:3250][3375050] Child process with pid: 3381751 was killed by signal: 9, core dumped: no
[UID:3250][1825045] Reached max children process limit: 6, extra: 2, current: 8, busy: 8, please increase LSAPI_CHILDREN.
[UID:3250][1825045] Reached max children process limit: 6, extra: 2, current: 8, busy: 8, please increase LSAPI_CHILDREN.
[UID:3250][1825045] Reached max children process limit: 6, extra: 2, current: 8, busy: 8, please increase LSAPI_CHILDREN.
[UID:3250][1825045] Reached max children process limit: 6, extra: 2, current: 8, busy: 8, please increase LSAPI_CHILDREN.
[UID:3250][1825045] Reached max children process limit: 6, extra: 2, current: 8, busy: 8, please increase LSAPI_CHILDREN.
[UID:3250][1825045] Reached max children process limit: 6, extra: 2, current: 8, busy: 8, please increase LSAPI_CHILDREN.
[UID:3250][1825045] Reached max children process limit: 6, extra: 2, current: 8, busy: 8, please increase LSAPI_CHILDREN.
[UID:3250][1825045] Reached max children process limit: 6, extra: 2, current: 8, busy: 8, please increase LSAPI_CHILDREN.
[UID:3250][1825045] Reached max children process limit: 6, extra: 2, current: 8, busy: 8, please increase LSAPI_CHILDREN.
[UID:3250][1825045] Reached max children process limit: 6, extra: 2, current: 8, busy: 8, please increase LSAPI_CHILDREN.
[UID:3250][1825045] Reached max children process limit: 6, extra: 2, current: 8, busy: 8, please increase LSAPI_CHILDREN.
[UID:3250][1825045] Reached max children process limit: 6, extra: 2, current: 8, busy: 8, please increase LSAPI_CHILDREN.
[UID:3250][1825045] Reached max children process limit: 6, extra: 2, current: 8, busy: 8, please increase LSAPI_CHILDREN.
[UID:3250][1825045] Reached max children process limit: 6, extra: 2, current: 8, busy: 8, please increase LSAPI_CHILDREN.
[UID:3250][1825045] Reached max children process limit: 6, extra: 2, current: 8, busy: 8, please increase LSAPI_CHILDREN.
[UID:3250][1825045] Reached max children process limit: 6, extra: 2, current: 8, busy: 8, please increase LSAPI_CHILDREN.
[UID:3250][1825045] Reached max children process limit: 6, extra: 2, current: 8, busy: 8, please increase LSAPI_CHILDREN.
[UID:3250][1825045] Reached max children process limit: 6, extra: 2, current: 8, busy: 8, please increase LSAPI_CHILDREN.
[UID:3250][1825045] Reached max children process limit: 6, extra: 2, current: 8, busy: 8, please increase LSAPI_CHILDREN.
[UID:3250][1825045] Reached max children process limit: 6, extra: 2, current: 8, busy: 8, please increase LSAPI_CHILDREN.
[UID:3250][1825045] Reached max children process limit: 6, extra: 2, current: 8, busy: 8, please increase LSAPI_CHILDREN.
[UID:3250][1825045] Reached max children process limit: 6, extra: 2, current: 8, busy: 8, please increase LSAPI_CHILDREN.
[UID:3250][1825045] Reached max children process limit: 6, extra: 2, current: 8, busy: 8, please increase LSAPI_CHILDREN.
[UID:3250][1825045] Reached max children process limit: 6, extra: 2, current: 8, busy: 8, please increase LSAPI_CHILDREN.
[UID:3250][1825045] Reached max children process limit: 6, extra: 2, current: 8, busy: 8, please increase LSAPI_CHILDREN.
[UID:3250][1825045] Reached max children process limit: 6, extra: 2, current: 8, busy: 8, please increase LSAPI_CHILDREN.
[UID:3250][1825045] Reached max children process limit: 6, extra: 2, current: 8, busy: 8, please increase LSAPI_CHILDREN.
[UID:3250][1825045] Reached max children process limit: 6, extra: 2, current: 8, busy: 8, please increase LSAPI_CHILDREN.
[UID:3250][1825045] Reached max children process limit: 6, extra: 2, current: 8, busy: 8, please increase LSAPI_CHILDREN.
[UID:3250][1825045] Reached max children process limit: 6, extra: 2, current: 8, busy: 8, please increase LSAPI_CHILDREN.
[UID:3250][1825045] Reached max children process limit: 6, extra: 2, current: 8, busy: 8, please increase LSAPI_CHILDREN.
[UID:3250][1825045] Reached max children process limit: 6, extra: 2, current: 8, busy: 8, please increase LSAPI_CHILDREN.
[UID:3250][1825045] Reached max children process limit: 6, extra: 2, current: 8, busy: 8, please increase LSAPI_CHILDREN.
[UID:3250][1825045] Reached max children process limit: 6, extra: 2, current: 8, busy: 8, please increase LSAPI_CHILDREN.
[UID:3250][1825045] Reached max children process limit: 6, extra: 2, current: 8, busy: 8, please increase LSAPI_CHILDREN.
[UID:3250][1825045] Reached max children process limit: 6, extra: 2, current: 8, busy: 8, please increase LSAPI_CHILDREN.
[UID:3250][1825045] Reached max children process limit: 6, extra: 2, current: 8, busy: 8, please increase LSAPI_CHILDREN.
[UID:3250][1825045] Reached max children process limit: 6, extra: 2, current: 8, busy: 8, please increase LSAPI_CHILDREN.
[UID:3250][1825045] Reached max children process limit: 6, extra: 2, current: 8, busy: 8, please increase LSAPI_CHILDREN.
[UID:3250][1825045] Reached max children process limit: 6, extra: 2, current: 8, busy: 8, please increase LSAPI_CHILDREN.
[UID:3250][1825045] Reached max children process limit: 6, extra: 2, current: 8, busy: 8, please increase LSAPI_CHILDREN.
[UID:3250][1825045] Reached max children process limit: 6, extra: 2, current: 8, busy: 8, please increase LSAPI_CHILDREN.
[UID:3250][1825045] Reached max children process limit: 6, extra: 2, current: 8, busy: 8, please increase LSAPI_CHILDREN.
[UID:3250][1825045] Reached max children process limit: 6, extra: 2, current: 8, busy: 8, please increase LSAPI_CHILDREN.
[UID:3250][1825045] Reached max children process limit: 6, extra: 2, current: 8, busy: 8, please increase LSAPI_CHILDREN.
[UID:3250][1825045] Reached max children process limit: 6, extra: 2, current: 8, busy: 8, please increase LSAPI_CHILDREN.
[UID:3250][1825045] Reached max children process limit: 6, extra: 2, current: 8, busy: 8, please increase LSAPI_CHILDREN.
[UID:3250][1825045] Reached max children process limit: 6, extra: 2, current: 8, busy: 8, please increase LSAPI_CHILDREN.
[UID:3250][3071056] Reached max children process limit: 6, extra: 2, current: 8, busy: 8, please increase LSAPI_CHILDREN.
[UID:3250][3071056] Reached max children process limit: 6, extra: 2, current: 8, busy: 8, please increase LSAPI_CHILDREN.
[UID:3250][3071056] Reached max children process limit: 6, extra: 2, current: 8, busy: 8, please increase LSAPI_CHILDREN.
[UID:3250][3071056] Reached max children process limit: 6, extra: 2, current: 8, busy: 8, please increase LSAPI_CHILDREN.
[UID:3250][3071056] Reached max children process limit: 6, extra: 2, current: 8, busy: 8, please increase LSAPI_CHILDREN.
[UID:3250][3071056] Reached max children process limit: 6, extra: 2, current: 8, busy: 8, please increase LSAPI_CHILDREN.
[UID:3250][3071056] Reached max children process limit: 6, extra: 2, current: 8, busy: 8, please increase LSAPI_CHILDREN.
[UID:3250][3071056] Reached max children process limit: 6, extra: 2, current: 8, busy: 8, please increase LSAPI_CHILDREN.
[UID:3250][3071056] Reached max children process limit: 6, extra: 2, current: 8, busy: 8, please increase LSAPI_CHILDREN.
[UID:3250][3071056] Reached max children process limit: 6, extra: 2, current: 8, busy: 8, please increase LSAPI_CHILDREN.
[UID:3250][3071056] Reached max children process limit: 6, extra: 2, current: 8, busy: 8, please increase LSAPI_CHILDREN.
[UID:3250][3071056] Reached max children process limit: 6, extra: 2, current: 8, busy: 8, please increase LSAPI_CHILDREN.
[UID:3250][3071056] Reached max children process limit: 6, extra: 2, current: 8, busy: 8, please increase LSAPI_CHILDREN.
[UID:3250][3071056] Reached max children process limit: 6, extra: 2, current: 8, busy: 8, please increase LSAPI_CHILDREN.
[UID:3250][3071056] Reached max children process limit: 6, extra: 2, current: 8, busy: 7, please increase LSAPI_CHILDREN.
[UID:3250][3071056] Reached max children process limit: 6, extra: 2, current: 8, busy: 7, please increase LSAPI_CHILDREN.
[UID:3250][3071056] Reached max children process limit: 6, extra: 2, current: 8, busy: 8, please increase LSAPI_CHILDREN.
[UID:3250][3071056] Reached max children process limit: 6, extra: 2, current: 8, busy: 8, please increase LSAPI_CHILDREN.
[UID:3250][3071056] Reached max children process limit: 6, extra: 2, current: 8, busy: 8, please increase LSAPI_CHILDREN.
[UID:3250][3071056] Reached max children process limit: 6, extra: 2, current: 8, busy: 8, please increase LSAPI_CHILDREN.
[UID:3250][3071056] Reached max children process limit: 6, extra: 2, current: 8, busy: 7, please increase LSAPI_CHILDREN.
[UID:3250][3071056] Reached max children process limit: 6, extra: 2, current: 8, busy: 8, please increase LSAPI_CHILDREN.
[UID:3250][3071056] Reached max children process limit: 6, extra: 2, current: 8, busy: 8, please increase LSAPI_CHILDREN.
Not Found: /
Invalid HTTP_HOST header: 'www.content.dgfs.mg'. You may need to add 'www.content.dgfs.mg' to ALLOWED_HOSTS.
Traceback (most recent call last):
  File "/home/dgfsmg/virtualenv/repositories/dgfs_back/3.10/lib/python3.10/site-packages/django/core/handlers/exception.py", line 55, in inner
    response = get_response(request)
  File "/home/dgfsmg/virtualenv/repositories/dgfs_back/3.10/lib/python3.10/site-packages/django/utils/deprecation.py", line 133, in __call__
    response = self.process_request(request)
  File "/home/dgfsmg/virtualenv/repositories/dgfs_back/3.10/lib/python3.10/site-packages/django/middleware/common.py", line 48, in process_request
    host = request.get_host()
  File "/home/dgfsmg/virtualenv/repositories/dgfs_back/3.10/lib/python3.10/site-packages/django/http/request.py", line 167, in get_host
    raise DisallowedHost(msg)
django.core.exceptions.DisallowedHost: Invalid HTTP_HOST header: 'www.content.dgfs.mg'. You may need to add 'www.content.dgfs.mg' to ALLOWED_HOSTS.
Bad Request: /
[UID:3250][2835455] Reached max children process limit: 6, extra: 2, current: 8, busy: 7, please increase LSAPI_CHILDREN.
[UID:3250][2835455] Reached max children process limit: 6, extra: 2, current: 8, busy: 8, please increase LSAPI_CHILDREN.
[UID:3250][2835455] Reached max children process limit: 6, extra: 2, current: 8, busy: 8, please increase LSAPI_CHILDREN.
[UID:3250][2835455] Reached max children process limit: 6, extra: 2, current: 8, busy: 8, please increase LSAPI_CHILDREN.
[UID:3250][2835455] Reached max children process limit: 6, extra: 2, current: 8, busy: 8, please increase LSAPI_CHILDREN.
[UID:3250][2835455] Reached max children process limit: 6, extra: 2, current: 8, busy: 8, please increase LSAPI_CHILDREN.
[UID:3250][2835455] Reached max children process limit: 6, extra: 2, current: 8, busy: 8, please increase LSAPI_CHILDREN.
[UID:3250][2835455] Reached max children process limit: 6, extra: 2, current: 8, busy: 8, please increase LSAPI_CHILDREN.
[UID:3250][2835455] Reached max children process limit: 6, extra: 2, current: 8, busy: 8, please increase LSAPI_CHILDREN.
[UID:3250][2835455] Reached max children process limit: 6, extra: 2, current: 8, busy: 8, please increase LSAPI_CHILDREN.
[UID:3250][2835455] Reached max children process limit: 6, extra: 2, current: 8, busy: 8, please increase LSAPI_CHILDREN.
[UID:3250][2835455] Reached max children process limit: 6, extra: 2, current: 8, busy: 8, please increase LSAPI_CHILDREN.
[UID:3250][2835455] Reached max children process limit: 6, extra: 2, current: 8, busy: 8, please increase LSAPI_CHILDREN.
[UID:3250][2835455] Reached max children process limit: 6, extra: 2, current: 8, busy: 8, please increase LSAPI_CHILDREN.
[UID:3250][2835455] Reached max children process limit: 6, extra: 2, current: 8, busy: 8, please increase LSAPI_CHILDREN.
